Traceback (most recent call last):
  File "/home/nightwish/elfin/main.py", line 12, in <module>
    from handlers.wechat import wechat
  File "/home/nightwish/elfin/handlers/wechat.py", line 13, in <module>
    from socrates.set import mongo
  File "/home/nightwish/elfin/socrates/set.py", line 9, in <module>
    level=logging.INFO
  File "/usr/lib/python2.7/logging/__init__.py", line 1528, in basicConfig
    hdlr = FileHandler(filename, mode)
  File "/usr/lib/python2.7/logging/__init__.py", line 901, in __init__
    StreamHandler.__init__(self, self._open())
  File "/usr/lib/python2.7/logging/__init__.py", line 924, in _open
    stream = open(self.baseFilename, self.mode)
IOError: [Errno 13] Permission denied: '/home/nightwish/elfin/log/run.log'
Traceback (most recent call last):
  File "/home/nightwish/elfin/main.py", line 12, in <module>
    from handlers.wechat import wechat
  File "/home/nightwish/elfin/handlers/wechat.py", line 13, in <module>
    from socrates.set import mongo
  File "/home/nightwish/elfin/socrates/set.py", line 9, in <module>
    level=logging.INFO
  File "/usr/lib/python2.7/logging/__init__.py", line 1528, in basicConfig
    hdlr = FileHandler(filename, mode)
  File "/usr/lib/python2.7/logging/__init__.py", line 901, in __init__
    StreamHandler.__init__(self, self._open())
  File "/usr/lib/python2.7/logging/__init__.py", line 924, in _open
    stream = open(self.baseFilename, self.mode)
IOError: [Errno 13] Permission denied: '/home/nightwish/elfin/log/run.log'
Traceback (most recent call last):
  File "/home/nightwish/elfin/main.py", line 12, in <module>
    from handlers.wechat import wechat
  File "/home/nightwish/elfin/handlers/wechat.py", line 13, in <module>
    from socrates.set import mongo
  File "/home/nightwish/elfin/socrates/set.py", line 9, in <module>
    level=logging.INFO
  File "/usr/lib/python2.7/logging/__init__.py", line 1528, in basicConfig
    hdlr = FileHandler(filename, mode)
  File "/usr/lib/python2.7/logging/__init__.py", line 901, in __init__
    StreamHandler.__init__(self, self._open())
  File "/usr/lib/python2.7/logging/__init__.py", line 924, in _open
    stream = open(self.baseFilename, self.mode)
IOError: [Errno 13] Permission denied: '/home/nightwish/elfin/log/run.log'
Traceback (most recent call last):
  File "/home/nightwish/elfin/main.py", line 12, in <module>
    from handlers.wechat import wechat
  File "/home/nightwish/elfin/handlers/wechat.py", line 13, in <module>
    from socrates.set import mongo
  File "/home/nightwish/elfin/socrates/set.py", line 9, in <module>
    level=logging.INFO
  File "/usr/lib/python2.7/logging/__init__.py", line 1528, in basicConfig
    hdlr = FileHandler(filename, mode)
  File "/usr/lib/python2.7/logging/__init__.py", line 901, in __init__
    StreamHandler.__init__(self, self._open())
  File "/usr/lib/python2.7/logging/__init__.py", line 924, in _open
    stream = open(self.baseFilename, self.mode)
IOError: [Errno 13] Permission denied: '/home/nightwish/elfin/log/run.log'
Traceback (most recent call last):
  File "/home/nightwish/elfin/scripts/get_access_token.py", line 14, in <module>
    from socrates.set import REDIS
  File "/home/nightwish/elfin/socrates/set.py", line 9, in <module>
    level=logging.INFO
  File "/usr/lib/python2.7/logging/__init__.py", line 1528, in basicConfig
    hdlr = FileHandler(filename, mode)
  File "/usr/lib/python2.7/logging/__init__.py", line 901, in __init__
    StreamHandler.__init__(self, self._open())
  File "/usr/lib/python2.7/logging/__init__.py", line 924, in _open
    stream = open(self.baseFilename, self.mode)
IOError: [Errno 13] Permission denied: '/home/nightwish/elfin/log/run.log'
Traceback (most recent call last):
  File "/home/nightwish/elfin/scripts/get_access_token.py", line 14, in <module>
    from socrates.set import REDIS
  File "/home/nightwish/elfin/socrates/set.py", line 9, in <module>
    level=logging.INFO
  File "/usr/lib/python2.7/logging/__init__.py", line 1528, in basicConfig
    hdlr = FileHandler(filename, mode)
  File "/usr/lib/python2.7/logging/__init__.py", line 901, in __init__
    StreamHandler.__init__(self, self._open())
  File "/usr/lib/python2.7/logging/__init__.py", line 924, in _open
    stream = open(self.baseFilename, self.mode)
IOError: [Errno 13] Permission denied: '/home/nightwish/elfin/log/run.log'
Traceback (most recent call last):
  File "/home/nightwish/elfin/scripts/get_access_token.py", line 14, in <module>
    from socrates.set import REDIS
  File "/home/nightwish/elfin/socrates/set.py", line 9, in <module>
    level=logging.INFO
  File "/usr/lib/python2.7/logging/__init__.py", line 1528, in basicConfig
    hdlr = FileHandler(filename, mode)
  File "/usr/lib/python2.7/logging/__init__.py", line 901, in __init__
    StreamHandler.__init__(self, self._open())
  File "/usr/lib/python2.7/logging/__init__.py", line 924, in _open
    stream = open(self.baseFilename, self.mode)
IOError: [Errno 13] Permission denied: '/home/nightwish/elfin/log/run.log'
Traceback (most recent call last):
  File "/home/nightwish/elfin/scripts/get_access_token.py", line 14, in <module>
    from socrates.set import REDIS
  File "/home/nightwish/elfin/socrates/set.py", line 9, in <module>
    level=logging.INFO
  File "/usr/lib/python2.7/logging/__init__.py", line 1528, in basicConfig
    hdlr = FileHandler(filename, mode)
  File "/usr/lib/python2.7/logging/__init__.py", line 901, in __init__
    StreamHandler.__init__(self, self._open())
  File "/usr/lib/python2.7/logging/__init__.py", line 924, in _open
    stream = open(self.baseFilename, self.mode)
IOError: [Errno 13] Permission denied: '/home/nightwish/elfin/log/run.log'
Traceback (most recent call last):
  File "/home/nightwish/elfin/main.py", line 14, in <module>
    from handlers.tail import *
  File "/home/nightwish/elfin/handlers/tail.py", line 9, in <module>
    sys.apth.append(os.path.abspath(os.path.join(os.path.dirname(__file__), os.path.pardir)))
AttributeError: 'module' object has no attribute 'apth'
Traceback (most recent call last):
  File "/home/nightwish/elfin/main.py", line 14, in <module>
    from handlers.tail import *
  File "/home/nightwish/elfin/handlers/tail.py", line 9, in <module>
    sys.apth.append(os.path.abspath(os.path.join(os.path.dirname(__file__), os.path.pardir)))
AttributeError: 'module' object has no attribute 'apth'
Traceback (most recent call last):
  File "/home/nightwish/elfin/main.py", line 14, in <module>
    from handlers.tail import *
  File "/home/nightwish/elfin/handlers/tail.py", line 9, in <module>
    sys.apth.append(os.path.abspath(os.path.join(os.path.dirname(__file__), os.path.pardir)))
AttributeError: 'module' object has no attribute 'apth'
Traceback (most recent call last):
  File "/home/nightwish/elfin/main.py", line 14, in <module>
    from handlers.tail import *
  File "/home/nightwish/elfin/handlers/tail.py", line 9, in <module>
    sys.apth.append(os.path.abspath(os.path.join(os.path.dirname(__file__), os.path.pardir)))
AttributeError: 'module' object has no attribute 'apth'
Traceback (most recent call last):
  File "/home/nightwish/elfin/main.py", line 14, in <module>
    from handlers.tail import *
  File "/home/nightwish/elfin/handlers/tail.py", line 11, in <module>
    from scripts import send_talk
  File "/home/nightwish/elfin/scripts/send_talk.py", line 16
    pwd = pwd_with_mail(pwd_with_mail.find(':') + 1:)
                                                   ^
SyntaxError: invalid syntax
Traceback (most recent call last):
  File "/home/nightwish/elfin/main.py", line 14, in <module>
    from handlers.tail import *
  File "/home/nightwish/elfin/handlers/tail.py", line 11, in <module>
    from scripts import send_talk
  File "/home/nightwish/elfin/scripts/send_talk.py", line 16
    pwd = pwd_with_mail(pwd_with_mail.find(':') + 1:)
                                                   ^
SyntaxError: invalid syntax
Traceback (most recent call last):
  File "/home/nightwish/elfin/main.py", line 14, in <module>
    from handlers.tail import *
  File "/home/nightwish/elfin/handlers/tail.py", line 11, in <module>
    from scripts import send_talk
  File "/home/nightwish/elfin/scripts/send_talk.py", line 16
    pwd = pwd_with_mail(pwd_with_mail.find(':') + 1:)
                                                   ^
SyntaxError: invalid syntax
Traceback (most recent call last):
  File "/home/nightwish/elfin/main.py", line 14, in <module>
    from handlers.tail import *
  File "/home/nightwish/elfin/handlers/tail.py", line 11, in <module>
    from scripts import send_talk
  File "/home/nightwish/elfin/scripts/send_talk.py", line 16
    pwd = pwd_with_mail(pwd_with_mail.find(':') + 1:)
                                                   ^
SyntaxError: invalid syntax
Traceback (most recent call last):
  File "/home/nightwish/elfin/main.py", line 12, in <module>
    from handlers.wechat import wechat
  File "/home/nightwish/elfin/handlers/wechat.py", line 16, in <module>
    from scripts.send_talk import send
  File "/home/nightwish/elfin/scripts/send_talk.py", line 56
    except AssertionError, e:
                            ^
IndentationError: unindent does not match any outer indentation level
Traceback (most recent call last):
  File "/home/nightwish/elfin/main.py", line 12, in <module>
    from handlers.wechat import wechat
  File "/home/nightwish/elfin/handlers/wechat.py", line 16, in <module>
    from scripts.send_talk import send
  File "/home/nightwish/elfin/scripts/send_talk.py", line 56
    except AssertionError, e:
                            ^
IndentationError: unindent does not match any outer indentation level
Traceback (most recent call last):
  File "/home/nightwish/elfin/main.py", line 12, in <module>
    from handlers.wechat import wechat
  File "/home/nightwish/elfin/handlers/wechat.py", line 16, in <module>
    from scripts.send_talk import send
  File "/home/nightwish/elfin/scripts/send_talk.py", line 56
    except AssertionError, e:
                            ^
IndentationError: unindent does not match any outer indentation level
Traceback (most recent call last):
  File "/home/nightwish/elfin/main.py", line 12, in <module>
    from handlers.wechat import wechat
  File "/home/nightwish/elfin/handlers/wechat.py", line 16, in <module>
    from scripts.send_talk import send
  File "/home/nightwish/elfin/scripts/send_talk.py", line 56
    except AssertionError, e:
                            ^
IndentationError: unindent does not match any outer indentation level
Traceback (most recent call last):
  File "/home/nightwish/elfin/main.py", line 12, in <module>
    from handlers.wechat import wechat
  File "/home/nightwish/elfin/handlers/wechat.py", line 16, in <module>
    from scripts.send_talk import send
  File "/home/nightwish/elfin/scripts/send_talk.py", line 23
    assert new_hash!==old_hash, hanzi.REPEAT
                     ^
SyntaxError: invalid syntax
Traceback (most recent call last):
  File "/home/nightwish/elfin/main.py", line 12, in <module>
    from handlers.wechat import wechat
  File "/home/nightwish/elfin/handlers/wechat.py", line 16, in <module>
    from scripts.send_talk import send
  File "/home/nightwish/elfin/scripts/send_talk.py", line 23
    assert new_hash!==old_hash, hanzi.REPEAT
                     ^
SyntaxError: invalid syntax
Traceback (most recent call last):
  File "/home/nightwish/elfin/main.py", line 12, in <module>
    from handlers.wechat import wechat
  File "/home/nightwish/elfin/handlers/wechat.py", line 16, in <module>
    from scripts.send_talk import send
  File "/home/nightwish/elfin/scripts/send_talk.py", line 23
    assert new_hash!==old_hash, hanzi.REPEAT
                     ^
SyntaxError: invalid syntax
Traceback (most recent call last):
  File "/home/nightwish/elfin/main.py", line 12, in <module>
    from handlers.wechat import wechat
  File "/home/nightwish/elfin/handlers/wechat.py", line 16, in <module>
    from scripts.send_talk import send
  File "/home/nightwish/elfin/scripts/send_talk.py", line 23
    assert new_hash!==old_hash, hanzi.REPEAT
                     ^
SyntaxError: invalid syntax
Traceback (most recent call last):
  File "/home/nightwish/elfin/main.py", line 12, in <module>
    from handlers.wechat import wechat
  File "/home/nightwish/elfin/handlers/wechat.py", line 17, in <module>
    from scripts.home import home
  File "/home/nightwish/elfin/scripts/home.py", line 10
    'home2':2
          ^
SyntaxError: invalid syntax
Traceback (most recent call last):
  File "/home/nightwish/elfin/main.py", line 12, in <module>
    from handlers.wechat import wechat
  File "/home/nightwish/elfin/handlers/wechat.py", line 17, in <module>
    from scripts.home import home
  File "/home/nightwish/elfin/scripts/home.py", line 10
    'home2':2
          ^
SyntaxError: invalid syntax
Traceback (most recent call last):
  File "/home/nightwish/elfin/main.py", line 12, in <module>
    from handlers.wechat import wechat
  File "/home/nightwish/elfin/handlers/wechat.py", line 17, in <module>
    from scripts.home import home
  File "/home/nightwish/elfin/scripts/home.py", line 10
    'home2':2
          ^
SyntaxError: invalid syntax
Traceback (most recent call last):
  File "/home/nightwish/elfin/main.py", line 12, in <module>
    from handlers.wechat import wechat
  File "/home/nightwish/elfin/handlers/wechat.py", line 17, in <module>
    from scripts.home import home
  File "/home/nightwish/elfin/scripts/home.py", line 10
    'home2':2
          ^
SyntaxError: invalid syntax
Traceback (most recent call last):
  File "/home/nightwish/elfin/main.py", line 12, in <module>
    from handlers.wechat import wechat
  File "/home/nightwish/elfin/handlers/wechat.py", line 17, in <module>
    from scripts.send_photo import upload_photo
  File "/home/nightwish/elfin/scripts/send_photo.py", line 51
    r = session.post(upload_photo_url, data=data, files={'photo':('1.jpg', photo, 'image/jpeg'})
                                                                                              ^
SyntaxError: invalid syntax
Traceback (most recent call last):
  File "/home/nightwish/elfin/main.py", line 12, in <module>
    from handlers.wechat import wechat
  File "/home/nightwish/elfin/handlers/wechat.py", line 17, in <module>
    from scripts.send_photo import upload_photo
  File "/home/nightwish/elfin/scripts/send_photo.py", line 51
    r = session.post(upload_photo_url, data=data, files={'photo':('1.jpg', photo, 'image/jpeg'})
                                                                                              ^
SyntaxError: invalid syntax
Traceback (most recent call last):
  File "/home/nightwish/elfin/main.py", line 12, in <module>
    from handlers.wechat import wechat
  File "/home/nightwish/elfin/handlers/wechat.py", line 17, in <module>
    from scripts.send_photo import upload_photo
  File "/home/nightwish/elfin/scripts/send_photo.py", line 51
    r = session.post(upload_photo_url, data=data, files={'photo':('1.jpg', photo, 'image/jpeg'})
                                                                                              ^
SyntaxError: invalid syntax
Traceback (most recent call last):
  File "/home/nightwish/elfin/main.py", line 12, in <module>
    from handlers.wechat import wechat
  File "/home/nightwish/elfin/handlers/wechat.py", line 17, in <module>
    from scripts.send_photo import upload_photo
  File "/home/nightwish/elfin/scripts/send_photo.py", line 51
    r = session.post(upload_photo_url, data=data, files={'photo':('1.jpg', photo, 'image/jpeg'})
                                                                                              ^
SyntaxError: invalid syntax
Traceback (most recent call last):
  File "/home/nightwish/elfin/main.py", line 14, in <module>
    from handlers.userset import userset
  File "/home/nightwish/elfin/handlers/userset.py", line 10, in <module>
    from socrates import log
ImportError: cannot import name log
Traceback (most recent call last):
  File "/home/nightwish/elfin/main.py", line 14, in <module>
    from handlers.userset import userset
  File "/home/nightwish/elfin/handlers/userset.py", line 10, in <module>
    from socrates import log
ImportError: cannot import name log
Traceback (most recent call last):
  File "/home/nightwish/elfin/main.py", line 14, in <module>
    from handlers.userset import userset
  File "/home/nightwish/elfin/handlers/userset.py", line 10, in <module>
    from socrates import log
ImportError: cannot import name log
Traceback (most recent call last):
  File "/home/nightwish/elfin/main.py", line 14, in <module>
    from handlers.userset import userset
  File "/home/nightwish/elfin/handlers/userset.py", line 10, in <module>
    from socrates import log
ImportError: cannot import name log

*** FATAL CONFIG FILE ERROR ***
Reading the configuration file, at line 53
>>> 'logfile /var/log/redis/redis-server.log'
Can't open the log file: Permission denied
Traceback (most recent call last):
  File "/home/nightwish/elfin/scripts/get_access_token.py", line 14, in <module>
    from socrates.set import REDIS
  File "/home/nightwish/elfin/socrates/set.py", line 33, in <module>
    mongo = pymongo.MongoClient(host='localhost', port=27017)['elfin']
  File "build/bdist.linux-i686/egg/pymongo/mongo_client.py", line 366, in __init__
pymongo.errors.ConnectionFailure: [Errno 111] Connection refused
Traceback (most recent call last):
  File "/home/nightwish/elfin/main.py", line 12, in <module>
    from handlers.wechat import wechat
  File "/home/nightwish/elfin/handlers/wechat.py", line 13, in <module>
    from socrates.set import mongo
  File "/home/nightwish/elfin/socrates/set.py", line 33, in <module>
    mongo = pymongo.MongoClient(host='localhost', port=27017)['elfin']
  File "build/bdist.linux-i686/egg/pymongo/mongo_client.py", line 366, in __init__
pymongo.errors.ConnectionFailure: [Errno 111] Connection refused

*** FATAL CONFIG FILE ERROR ***
Reading the configuration file, at line 53
>>> 'logfile /var/log/redis/redis-server.log'
Can't open the log file: Permission denied
forked process: 21025
Traceback (most recent call last):
  File "/home/nightwish/elfin/scripts/get_access_token.py", line 14, in <module>
    from socrates.set import REDIS
  File "/home/nightwish/elfin/socrates/set.py", line 33, in <module>
    mongo = pymongo.MongoClient(host='localhost', port=27017)['elfin']
  File "build/bdist.linux-i686/egg/pymongo/mongo_client.py", line 366, in __init__
pymongo.errors.ConnectionFailure: [Errno 111] Connection refused
Traceback (most recent call last):
  File "/home/nightwish/elfin/main.py", line 12, in <module>
    from handlers.wechat import wechat
  File "/home/nightwish/elfin/handlers/wechat.py", line 13, in <module>
    from socrates.set import mongo
  File "/home/nightwish/elfin/socrates/set.py", line 33, in <module>
    mongo = pymongo.MongoClient(host='localhost', port=27017)['elfin']
  File "build/bdist.linux-i686/egg/pymongo/mongo_client.py", line 366, in __init__
pymongo.errors.ConnectionFailure: [Errno 111] Connection refused

*** FATAL CONFIG FILE ERROR ***
Reading the configuration file, at line 53
>>> 'logfile /var/log/redis/redis-server.log'
Can't open the log file: Permission denied
forked process: 21043
Traceback (most recent call last):
  File "/home/nightwish/elfin/scripts/get_access_token.py", line 14, in <module>
    from socrates.set import REDIS
  File "/home/nightwish/elfin/socrates/set.py", line 33, in <module>
    mongo = pymongo.MongoClient(host='localhost', port=27017)['elfin']
  File "build/bdist.linux-i686/egg/pymongo/mongo_client.py", line 366, in __init__
pymongo.errors.ConnectionFailure: [Errno 111] Connection refused
Traceback (most recent call last):
  File "/home/nightwish/elfin/main.py", line 12, in <module>
    from handlers.wechat import wechat
  File "/home/nightwish/elfin/handlers/wechat.py", line 13, in <module>
    from socrates.set import mongo
  File "/home/nightwish/elfin/socrates/set.py", line 33, in <module>
    mongo = pymongo.MongoClient(host='localhost', port=27017)['elfin']
  File "build/bdist.linux-i686/egg/pymongo/mongo_client.py", line 366, in __init__
pymongo.errors.ConnectionFailure: [Errno 111] Connection refused

*** FATAL CONFIG FILE ERROR ***
Reading the configuration file, at line 53
>>> 'logfile /var/log/redis/redis-server.log'
Can't open the log file: Permission denied
forked process: 21059
Traceback (most recent call last):
  File "/home/nightwish/elfin/scripts/get_access_token.py", line 14, in <module>
    from socrates.set import REDIS
  File "/home/nightwish/elfin/socrates/set.py", line 33, in <module>
    mongo = pymongo.MongoClient(host='localhost', port=27017)['elfin']
  File "build/bdist.linux-i686/egg/pymongo/mongo_client.py", line 366, in __init__
pymongo.errors.ConnectionFailure: [Errno 111] Connection refused
Traceback (most recent call last):
  File "/home/nightwish/elfin/main.py", line 12, in <module>
    from handlers.wechat import wechat
  File "/home/nightwish/elfin/handlers/wechat.py", line 13, in <module>
    from socrates.set import mongo
  File "/home/nightwish/elfin/socrates/set.py", line 33, in <module>
    mongo = pymongo.MongoClient(host='localhost', port=27017)['elfin']
  File "build/bdist.linux-i686/egg/pymongo/mongo_client.py", line 366, in __init__
pymongo.errors.ConnectionFailure: [Errno 111] Connection refused

*** FATAL CONFIG FILE ERROR ***
Reading the configuration file, at line 53
>>> 'logfile /var/log/redis/redis-server.log'
Can't open the log file: Permission denied

*** FATAL CONFIG FILE ERROR ***
Reading the configuration file, at line 53
>>> 'logfile /var/log/redis/redis-server.log'
Can't open the log file: Permission denied

*** FATAL CONFIG FILE ERROR ***
Reading the configuration file, at line 53
>>> 'logfile /var/log/redis/redis-server.log'
Can't open the log file: Permission denied

*** FATAL CONFIG FILE ERROR ***
Reading the configuration file, at line 53
>>> 'logfile /var/log/redis/redis-server.log'
Can't open the log file: Permission denied
forked process: 21080
forked process: 21087
forked process: 21112
forked process: 21120
forked process: 21138
forked process: 21145
forked process: 21152
forked process: 21159

*** FATAL CONFIG FILE ERROR ***
Reading the configuration file, at line 53
>>> 'logfile /var/log/redis/redis-server.log'
Can't open the log file: Permission denied

*** FATAL CONFIG FILE ERROR ***
Reading the configuration file, at line 53
>>> 'logfile /var/log/redis/redis-server.log'
Can't open the log file: Permission denied

*** FATAL CONFIG FILE ERROR ***
Reading the configuration file, at line 53
>>> 'logfile /var/log/redis/redis-server.log'
Can't open the log file: Permission denied

*** FATAL CONFIG FILE ERROR ***
Reading the configuration file, at line 53
>>> 'logfile /var/log/redis/redis-server.log'
Can't open the log file: Permission denied
forked process: 21272
forked process: 21279
forked process: 21286
forked process: 21293
forked process: 21310
forked process: 21317
forked process: 21324
forked process: 21331
Traceback (most recent call last):
  File "/home/nightwish/elfin/scripts/get_access_token.py", line 14, in <module>
    from socrates.set import REDIS
  File "/home/nightwish/elfin/socrates/set.py", line 33, in <module>
    mongo = pymongo.MongoClient(host='localhost', port=27017)['elfin']
  File "build/bdist.linux-i686/egg/pymongo/mongo_client.py", line 366, in __init__
pymongo.errors.ConnectionFailure: [Errno 111] Connection refused
Traceback (most recent call last):
  File "/home/nightwish/elfin/scripts/get_access_token.py", line 14, in <module>
    from socrates.set import REDIS
  File "/home/nightwish/elfin/socrates/set.py", line 33, in <module>
    mongo = pymongo.MongoClient(host='localhost', port=27017)['elfin']
  File "build/bdist.linux-i686/egg/pymongo/mongo_client.py", line 366, in __init__
pymongo.errors.ConnectionFailure: [Errno 111] Connection refused
Traceback (most recent call last):
  File "/home/nightwish/elfin/scripts/get_access_token.py", line 14, in <module>
    from socrates.set import REDIS
  File "/home/nightwish/elfin/socrates/set.py", line 33, in <module>
    mongo = pymongo.MongoClient(host='localhost', port=27017)['elfin']
  File "build/bdist.linux-i686/egg/pymongo/mongo_client.py", line 366, in __init__
pymongo.errors.ConnectionFailure: [Errno 111] Connection refused
Traceback (most recent call last):
  File "/home/nightwish/elfin/scripts/get_access_token.py", line 14, in <module>
    from socrates.set import REDIS
  File "/home/nightwish/elfin/socrates/set.py", line 33, in <module>
    mongo = pymongo.MongoClient(host='localhost', port=27017)['elfin']
  File "build/bdist.linux-i686/egg/pymongo/mongo_client.py", line 366, in __init__
pymongo.errors.ConnectionFailure: [Errno 111] Connection refused
forked process: 21365
forked process: 21372
forked process: 21379
forked process: 21386
forked process: 21423
forked process: 21446
forked process: 21453
forked process: 21498
all output going to: /home/nightwish/elfin/log/mongo.log
forked process: 21505
forked process: 21512
forked process: 21519
forked process: 21526
forked process: 21561
forked process: 21573
forked process: 21585
forked process: 21638
forked process: 21650
forked process: 21662
forked process: 21706
forked process: 21718
forked process: 21730
forked process: 21742
forked process: 21764
forked process: 21782
forked process: 21789
all output going to: /home/nightwish/elfin/log/mongo.log
all output going to: /home/nightwish/elfin/log/mongo.log
Traceback (most recent call last):
  File "/home/nightwish/elfin/main.py", line 12, in <module>
    from handlers.wechat import wechat
  File "/home/nightwish/elfin/handlers/wechat.py", line 18, in <module>
    from scripts.send_photo import upload_photo
  File "/home/nightwish/elfin/scripts/send_photo.py", line 10, in <module>
    from scripts.send_talk import send_ok_ret
ImportError: cannot import name send_ok_ret
Traceback (most recent call last):
  File "/home/nightwish/elfin/main.py", line 12, in <module>
    from handlers.wechat import wechat
  File "/home/nightwish/elfin/handlers/wechat.py", line 18, in <module>
    from scripts.send_photo import upload_photo
  File "/home/nightwish/elfin/scripts/send_photo.py", line 10, in <module>
    from scripts.send_talk import send_ok_ret
ImportError: cannot import name send_ok_ret
Traceback (most recent call last):
  File "/home/nightwish/elfin/main.py", line 12, in <module>
    from handlers.wechat import wechat
  File "/home/nightwish/elfin/handlers/wechat.py", line 18, in <module>
    from scripts.send_photo import upload_photo
  File "/home/nightwish/elfin/scripts/send_photo.py", line 10, in <module>
    from scripts.send_talk import send_ok_ret
ImportError: cannot import name send_ok_ret
Traceback (most recent call last):
  File "/home/nightwish/elfin/main.py", line 12, in <module>
    from handlers.wechat import wechat
  File "/home/nightwish/elfin/handlers/wechat.py", line 18, in <module>
    from scripts.send_photo import upload_photo
  File "/home/nightwish/elfin/scripts/send_photo.py", line 10, in <module>
    from scripts.send_talk import send_ok_ret
ImportError: cannot import name send_ok_ret
Traceback (most recent call last):
  File "/home/nightwish/elfin/main.py", line 12, in <module>
    from handlers.wechat import wechat
  File "/home/nightwish/elfin/handlers/wechat.py", line 18, in <module>
    from scripts.send_photo import upload_photo
  File "/home/nightwish/elfin/scripts/send_photo.py", line 10, in <module>
    from scripts.send_talk import send_ok_ret
ImportError: cannot import name send_ok_ret
Traceback (most recent call last):
  File "/home/nightwish/elfin/main.py", line 12, in <module>
    from handlers.wechat import wechat
  File "/home/nightwish/elfin/handlers/wechat.py", line 18, in <module>
    from scripts.send_photo import upload_photo
  File "/home/nightwish/elfin/scripts/send_photo.py", line 10, in <module>
    from scripts.send_talk import send_ok_ret
ImportError: cannot import name send_ok_ret
Traceback (most recent call last):
  File "/home/nightwish/elfin/main.py", line 12, in <module>
    from handlers.wechat import wechat
  File "/home/nightwish/elfin/handlers/wechat.py", line 18, in <module>
    from scripts.send_photo import upload_photo
  File "/home/nightwish/elfin/scripts/send_photo.py", line 10, in <module>
    from scripts.send_talk import send_ok_ret
ImportError: cannot import name send_ok_ret
Traceback (most recent call last):
  File "/home/nightwish/elfin/main.py", line 12, in <module>
    from handlers.wechat import wechat
  File "/home/nightwish/elfin/handlers/wechat.py", line 18, in <module>
    from scripts.send_photo import upload_photo
  File "/home/nightwish/elfin/scripts/send_photo.py", line 10, in <module>
    from scripts.send_talk import send_ok_ret
ImportError: cannot import name send_ok_ret
Traceback (most recent call last):
  File "/home/nightwish/elfin/local/lib/python2.7/site-packages/gevent/greenlet.py", line 327, in run
    result = self._run(*self.args, **self.kwargs)
AttributeError: 'Greenlet' object has no attribute '_run'
<Greenlet at 0xa66057c> failed with AttributeError

Traceback (most recent call last):
  File "/home/nightwish/elfin/local/lib/python2.7/site-packages/gevent/greenlet.py", line 327, in run
    result = self._run(*self.args, **self.kwargs)
AttributeError: 'Greenlet' object has no attribute '_run'
<Greenlet at 0xa660a7c> failed with AttributeError

Traceback (most recent call last):
  File "/home/nightwish/elfin/local/lib/python2.7/site-packages/gevent/greenlet.py", line 327, in run
    result = self._run(*self.args, **self.kwargs)
AttributeError: 'Greenlet' object has no attribute '_run'
<Greenlet at 0x8a81e3c> failed with AttributeError

Traceback (most recent call last):
  File "/home/nightwish/elfin/local/lib/python2.7/site-packages/gevent/greenlet.py", line 327, in run
    result = self._run(*self.args, **self.kwargs)
AttributeError: 'Greenlet' object has no attribute '_run'
<Greenlet at 0x8ad184c> failed with AttributeError

Traceback (most recent call last):
  File "/home/nightwish/elfin/local/lib/python2.7/site-packages/gevent/greenlet.py", line 327, in run
    result = self._run(*self.args, **self.kwargs)
AttributeError: 'Greenlet' object has no attribute '_run'
<Greenlet at 0x8a81e3c> failed with AttributeError

Traceback (most recent call last):
  File "/home/nightwish/elfin/local/lib/python2.7/site-packages/gevent/greenlet.py", line 327, in run
    result = self._run(*self.args, **self.kwargs)
AttributeError: 'Greenlet' object has no attribute '_run'
<Greenlet at 0x8ad125c> failed with AttributeError

Traceback (most recent call last):
  File "/home/nightwish/elfin/local/lib/python2.7/site-packages/gevent/greenlet.py", line 327, in run
    result = self._run(*self.args, **self.kwargs)
AttributeError: 'Greenlet' object has no attribute '_run'
<Greenlet at 0x9070e3c> failed with AttributeError

Traceback (most recent call last):
  File "/home/nightwish/elfin/local/lib/python2.7/site-packages/gevent/greenlet.py", line 327, in run
    result = self._run(*self.args, **self.kwargs)
AttributeError: 'Greenlet' object has no attribute '_run'
<Greenlet at 0x90c084c> failed with AttributeError

all output going to: /home/nightwish/elfin/log/mongo.log
Traceback (most recent call last):
  File "/home/nightwish/elfin/local/lib/python2.7/site-packages/gevent/greenlet.py", line 327, in run
    result = self._run(*self.args, **self.kwargs)
  File "/home/nightwish/elfin/scripts/simi.py", line 17, in simi
    return respons['response']
KeyError: 'response'
<Greenlet at 0x9a372ac: simi(u'\u3002\u3002\u3002\u3002')> failed with KeyError

Traceback (most recent call last):
  File "/home/nightwish/elfin/local/lib/python2.7/site-packages/gevent/greenlet.py", line 327, in run
    result = self._run(*self.args, **self.kwargs)
  File "/home/nightwish/elfin/scripts/simi.py", line 17, in simi
    return respons['response']
KeyError: 'response'
<Greenlet at 0xa30fcac: simi('sendfromOneisAll.')> failed with KeyError

Traceback (most recent call last):
  File "/home/nightwish/elfin/local/lib/python2.7/site-packages/gevent/greenlet.py", line 327, in run
    result = self._run(*self.args, **self.kwargs)
  File "/home/nightwish/elfin/scripts/simi.py", line 17, in simi
    return respons['response']
KeyError: 'response'
<Greenlet at 0xa30fcac: simi(u'\u3002\u3002\u3002\u3002')> failed with KeyError

Traceback (most recent call last):
  File "/home/nightwish/elfin/local/lib/python2.7/site-packages/gevent/greenlet.py", line 327, in run
    result = self._run(*self.args, **self.kwargs)
  File "/home/nightwish/elfin/scripts/simi.py", line 17, in simi
    return respons['response']
KeyError: 'response'
<Greenlet at 0xa30fcac: simi('TESTagain')> failed with KeyError

Traceback (most recent call last):
  File "/home/nightwish/elfin/local/lib/python2.7/site-packages/gevent/greenlet.py", line 327, in run
    result = self._run(*self.args, **self.kwargs)
  File "/home/nightwish/elfin/scripts/simi.py", line 17, in simi
    return respons['response']
KeyError: 'response'
<Greenlet at 0xa5b043c: simi(u'\u662f\u554a\u6211\u60f3\u4f60\u4e86\u5462\uff01)> failed with KeyError

Traceback (most recent call last):
  File "/home/nightwish/elfin/local/lib/python2.7/site-packages/gevent/greenlet.py", line 327, in run
    result = self._run(*self.args, **self.kwargs)
  File "/home/nightwish/elfin/scripts/simi.py", line 17, in simi
    return respons['response']
KeyError: 'response'
<Greenlet at 0xa5b043c: simi(u'why\uff01')> failed with KeyError

Traceback (most recent call last):
  File "/home/nightwish/elfin/local/lib/python2.7/site-packages/gevent/greenlet.py", line 327, in run
    result = self._run(*self.args, **self.kwargs)
  File "/home/nightwish/elfin/scripts/simi.py", line 17, in simi
    return respons['response']
KeyError: 'response'
<Greenlet at 0xa5b043c: simi(u'\U0001f60d')> failed with KeyError

Traceback (most recent call last):
  File "/home/nightwish/elfin/local/lib/python2.7/site-packages/gevent/greenlet.py", line 327, in run
    result = self._run(*self.args, **self.kwargs)
  File "/home/nightwish/elfin/scripts/simi.py", line 17, in simi
    return respons['response']
KeyError: 'response'
<Greenlet at 0xa5b052c: simi(u'\u5c0f\u722a \u4f60\u597d\u5440')> failed with KeyError

Traceback (most recent call last):
  File "/home/nightwish/elfin/local/lib/python2.7/site-packages/gevent/greenlet.py", line 327, in run
    result = self._run(*self.args, **self.kwargs)
  File "/home/nightwish/elfin/scripts/simi.py", line 17, in simi
    return respons['response']
KeyError: 'response'
<Greenlet at 0xa5b052c: simi(u'\u5c0f\u7cbe\u7075\uff0c\u600e\u4e48\u6539"\u676)> failed with KeyError

Traceback (most recent call last):
  File "/home/nightwish/elfin/local/lib/python2.7/site-packages/gevent/greenlet.py", line 327, in run
    result = self._run(*self.args, **self.kwargs)
  File "/home/nightwish/elfin/scripts/simi.py", line 17, in simi
    return respons['response']
KeyError: 'response'
<Greenlet at 0xa5b052c: simi(u'\u957f\u8349\u597d\u591a\uff0c\u53bb\u9996\u5c14)> failed with KeyError

Traceback (most recent call last):
  File "/home/nightwish/elfin/local/lib/python2.7/site-packages/gevent/greenlet.py", line 327, in run
    result = self._run(*self.args, **self.kwargs)
  File "/home/nightwish/elfin/scripts/simi.py", line 17, in simi
    return respons['response']
KeyError: 'response'
<Greenlet at 0xa5b0cac: simi('hello')> failed with KeyError

Traceback (most recent call last):
  File "/home/nightwish/elfin/local/lib/python2.7/site-packages/gevent/greenlet.py", line 327, in run
    result = self._run(*self.args, **self.kwargs)
  File "/home/nightwish/elfin/scripts/simi.py", line 17, in simi
    return respons['response']
KeyError: 'response'
<Greenlet at 0xa5b0cac: simi('none')> failed with KeyError

Traceback (most recent call last):
  File "/home/nightwish/elfin/local/lib/python2.7/site-packages/gevent/greenlet.py", line 327, in run
    result = self._run(*self.args, **self.kwargs)
  File "/home/nightwish/elfin/scripts/simi.py", line 17, in simi
    return respons['response']
KeyError: 'response'
<Greenlet at 0xa5b0cac: simi(u'\u54c7\uff0c\u65b0\u7248\u672c\u597d\u9ad8\u5927)> failed with KeyError

Traceback (most recent call last):
  File "/home/nightwish/elfin/local/lib/python2.7/site-packages/gevent/greenlet.py", line 327, in run
    result = self._run(*self.args, **self.kwargs)
  File "/home/nightwish/elfin/scripts/simi.py", line 17, in simi
    return respons['response']
KeyError: 'response'
<Greenlet at 0xa5b0cac: simi(u'\u4e48\u4e48\u54d2')> failed with KeyError

Traceback (most recent call last):
  File "/home/nightwish/elfin/local/lib/python2.7/site-packages/gevent/greenlet.py", line 327, in run
    result = self._run(*self.args, **self.kwargs)
  File "/home/nightwish/elfin/scripts/simi.py", line 17, in simi
    return respons['response']
KeyError: 'response'
<Greenlet at 0xa5b0cac: simi(u'\u4eba\u554a\uff0c\u8981\u52c7\u6562\u7684\u544a)> failed with KeyError

Traceback (most recent call last):
  File "/home/nightwish/elfin/local/lib/python2.7/site-packages/gevent/greenlet.py", line 327, in run
    result = self._run(*self.args, **self.kwargs)
  File "/home/nightwish/elfin/scripts/simi.py", line 17, in simi
    return respons['response']
KeyError: 'response'
<Greenlet at 0xa5b0cac: simi(u'\u6709\u5957\u5316\u5986\u54c1\u6211\u540c\u4e8b)> failed with KeyError

Traceback (most recent call last):
  File "/home/nightwish/elfin/local/lib/python2.7/site-packages/gevent/greenlet.py", line 327, in run
    result = self._run(*self.args, **self.kwargs)
  File "/home/nightwish/elfin/scripts/simi.py", line 17, in simi
    return respons['response']
KeyError: 'response'
<Greenlet at 0xa5b0e8c: simi(u'\u4eba\u554a\uff0c\u8981\u52c7\u6562\u7684\u544a)> failed with KeyError

Traceback (most recent call last):
  File "/home/nightwish/elfin/local/lib/python2.7/site-packages/gevent/greenlet.py", line 327, in run
    result = self._run(*self.args, **self.kwargs)
  File "/home/nightwish/elfin/scripts/simi.py", line 17, in simi
    return respons['response']
KeyError: 'response'
<Greenlet at 0xa5b043c: simi(u'\u6765\u4eba \u7ed9\u6715\u4e0a\u4e00\u76d8\u5c0)> failed with KeyError

Traceback (most recent call last):
  File "/home/nightwish/elfin/local/lib/python2.7/site-packages/gevent/greenlet.py", line 327, in run
    result = self._run(*self.args, **self.kwargs)
  File "/home/nightwish/elfin/scripts/simi.py", line 17, in simi
    return respons['response']
KeyError: 'response'
<Greenlet at 0xa5b043c: simi(u'\u4f3c\u4e4e\u4f20\u56fe\u7247\u4e0d\u80fd\u4e48)> failed with KeyError

Traceback (most recent call last):
  File "/home/nightwish/elfin/local/lib/python2.7/site-packages/gevent/greenlet.py", line 327, in run
    result = self._run(*self.args, **self.kwargs)
  File "/home/nightwish/elfin/scripts/simi.py", line 17, in simi
    return respons['response']
KeyError: 'response'
<Greenlet at 0xa5b043c: simi(u'\u5c0f\u5c0f\u9ec4\u9e21\u8fd8\u60f3\u6297\u65e8)> failed with KeyError

Traceback (most recent call last):
  File "/home/nightwish/elfin/local/lib/python2.7/site-packages/gevent/greenlet.py", line 327, in run
    result = self._run(*self.args, **self.kwargs)
  File "/home/nightwish/elfin/scripts/simi.py", line 17, in simi
    return respons['response']
KeyError: 'response'
<Greenlet at 0xa5b043c: simi(u'\u6d4b\u8bd5\u53d1\u9001')> failed with KeyError

Traceback (most recent call last):
  File "/home/nightwish/elfin/local/lib/python2.7/site-packages/gevent/greenlet.py", line 327, in run
    result = self._run(*self.args, **self.kwargs)
  File "/home/nightwish/elfin/scripts/simi.py", line 17, in simi
    return respons['response']
KeyError: 'response'
<Greenlet at 0xa5b043c: simi(u'\u88d9\u5b50')> failed with KeyError

Traceback (most recent call last):
  File "/home/nightwish/elfin/local/lib/python2.7/site-packages/gevent/greenlet.py", line 327, in run
    result = self._run(*self.args, **self.kwargs)
  File "/home/nightwish/elfin/scripts/simi.py", line 17, in simi
    return respons['response']
KeyError: 'response'
<Greenlet at 0xa5b043c: simi(u'\u4e03\u5915\u5feb\u4e50')> failed with KeyError

Traceback (most recent call last):
  File "/home/nightwish/elfin/local/lib/python2.7/site-packages/gevent/greenlet.py", line 327, in run
    result = self._run(*self.args, **self.kwargs)
  File "/home/nightwish/elfin/scripts/simi.py", line 17, in simi
    return respons['response']
KeyError: 'response'
<Greenlet at 0xa5b0bbc: simi(u'\u5e72\u561b\u8bf4\u6211\u91cd\u590d\u53d1\u9001)> failed with KeyError

Traceback (most recent call last):
  File "/home/nightwish/elfin/local/lib/python2.7/site-packages/gevent/greenlet.py", line 327, in run
    result = self._run(*self.args, **self.kwargs)
  File "/home/nightwish/elfin/scripts/simi.py", line 17, in simi
    return respons['response']
KeyError: 'response'
<Greenlet at 0xa5b0bbc: simi(u'\u597d\u70ed\u2265\ufe4f\u2264')> failed with KeyError

Traceback (most recent call last):
  File "/home/nightwish/elfin/local/lib/python2.7/site-packages/gevent/greenlet.py", line 327, in run
    result = self._run(*self.args, **self.kwargs)
  File "/home/nightwish/elfin/scripts/simi.py", line 17, in simi
    return respons['response']
KeyError: 'response'
<Greenlet at 0xa5b0bbc: simi(u'\u70e6\u6b7b\u4eba\u4e86\u600e\u4e48\u7834\uff1f)> failed with KeyError

Traceback (most recent call last):
  File "/home/nightwish/elfin/local/lib/python2.7/site-packages/gevent/greenlet.py", line 327, in run
    result = self._run(*self.args, **self.kwargs)
  File "/home/nightwish/elfin/scripts/simi.py", line 17, in simi
    return respons['response']
KeyError: 'response'
<Greenlet at 0xa30f20c: simi(u'\u70e6\u6b7b\u4eba\u4e86\u600e\u4e48\u7834\uff1f)> failed with KeyError

Traceback (most recent call last):
  File "/home/nightwish/elfin/local/lib/python2.7/site-packages/gevent/greenlet.py", line 327, in run
    result = self._run(*self.args, **self.kwargs)
  File "/home/nightwish/elfin/scripts/simi.py", line 17, in simi
    return respons['response']
KeyError: 'response'
<Greenlet at 0xa30f20c: simi(u'\u5c0f\u9ec4\u9e21\u90fd\u4e0d\u7406\u6211\uff0c)> failed with KeyError

Traceback (most recent call last):
  File "/home/nightwish/elfin/local/lib/python2.7/site-packages/gevent/greenlet.py", line 327, in run
    result = self._run(*self.args, **self.kwargs)
  File "/home/nightwish/elfin/scripts/simi.py", line 17, in simi
    return respons['response']
KeyError: 'response'
<Greenlet at 0xa30f20c: simi(u'what\uff1f')> failed with KeyError

Traceback (most recent call last):
  File "/home/nightwish/elfin/local/lib/python2.7/site-packages/gevent/greenlet.py", line 327, in run
    result = self._run(*self.args, **self.kwargs)
  File "/home/nightwish/elfin/scripts/simi.py", line 17, in simi
    return respons['response']
KeyError: 'response'
<Greenlet at 0xa30f20c: simi(u'\u8fd9\u6837\u5c31\u7ed1\u597d\u4e86\u662f\u4e0d)> failed with KeyError

Traceback (most recent call last):
  File "/home/nightwish/elfin/local/lib/python2.7/site-packages/gevent/greenlet.py", line 327, in run
    result = self._run(*self.args, **self.kwargs)
  File "/home/nightwish/elfin/scripts/simi.py", line 17, in simi
    return respons['response']
KeyError: 'response'
<Greenlet at 0xa30f20c: simi(u'\uff1f')> failed with KeyError

Traceback (most recent call last):
  File "/home/nightwish/elfin/local/lib/python2.7/site-packages/gevent/greenlet.py", line 327, in run
    result = self._run(*self.args, **self.kwargs)
  File "/home/nightwish/elfin/scripts/simi.py", line 17, in simi
    return respons['response']
KeyError: 'response'
<Greenlet at 0xa30f20c: simi(u'\u4f60\u56de\u4e2aNone\u662f\u561b\u610f\u601d\u)> failed with KeyError

Traceback (most recent call last):
  File "/home/nightwish/elfin/local/lib/python2.7/site-packages/gevent/greenlet.py", line 327, in run
    result = self._run(*self.args, **self.kwargs)
  File "/home/nightwish/elfin/scripts/simi.py", line 17, in simi
    return respons['response']
KeyError: 'response'
<Greenlet at 0xa30f20c: simi('Hello')> failed with KeyError

Traceback (most recent call last):
  File "/home/nightwish/elfin/local/lib/python2.7/site-packages/gevent/greenlet.py", line 327, in run
    result = self._run(*self.args, **self.kwargs)
  File "/home/nightwish/elfin/scripts/simi.py", line 17, in simi
    return respons['response']
KeyError: 'response'
<Greenlet at 0xa30f20c: simi('3')> failed with KeyError

Traceback (most recent call last):
  File "/home/nightwish/elfin/local/lib/python2.7/site-packages/gevent/greenlet.py", line 327, in run
    result = self._run(*self.args, **self.kwargs)
  File "/home/nightwish/elfin/scripts/simi.py", line 17, in simi
    return respons['response']
KeyError: 'response'
<Greenlet at 0xa30f20c: simi('Sodagreen')> failed with KeyError

Traceback (most recent call last):
  File "/home/nightwish/elfin/local/lib/python2.7/site-packages/gevent/greenlet.py", line 327, in run
    result = self._run(*self.args, **self.kwargs)
  File "/home/nightwish/elfin/scripts/simi.py", line 17, in simi
    return respons['response']
KeyError: 'response'
<Greenlet at 0xa30f20c: simi(u'\u5c0f\u9ec4\uff0c\u4f60\u6362\u4e2a\u8bdd\u9898)> failed with KeyError

Traceback (most recent call last):
  File "/home/nightwish/elfin/local/lib/python2.7/site-packages/gevent/greenlet.py", line 327, in run
    result = self._run(*self.args, **self.kwargs)
  File "/home/nightwish/elfin/scripts/simi.py", line 17, in simi
    return respons['response']
KeyError: 'response'
<Greenlet at 0xa30f20c: simi('....')> failed with KeyError

Traceback (most recent call last):
  File "/home/nightwish/elfin/local/lib/python2.7/site-packages/gevent/greenlet.py", line 327, in run
    result = self._run(*self.args, **self.kwargs)
  File "/home/nightwish/elfin/scripts/simi.py", line 17, in simi
    return respons['response']
KeyError: 'response'
<Greenlet at 0xa30f20c: simi(u'\u4eca\u5929\u4e2d\u73ed \u4e2d\u5348\u534a\u789)> failed with KeyError

Traceback (most recent call last):
  File "/home/nightwish/elfin/local/lib/python2.7/site-packages/gevent/greenlet.py", line 327, in run
    result = self._run(*self.args, **self.kwargs)
  File "/home/nightwish/elfin/scripts/simi.py", line 17, in simi
    return respons['response']
KeyError: 'response'
<Greenlet at 0xa30f20c: simi(u'\u660e\u5929\u591c\u73ed\u2026\u2026\u4e0d\u8981)> failed with KeyError

Traceback (most recent call last):
  File "/home/nightwish/elfin/local/lib/python2.7/site-packages/gevent/greenlet.py", line 327, in run
    result = self._run(*self.args, **self.kwargs)
  File "/home/nightwish/elfin/scripts/simi.py", line 17, in simi
    return respons['response']
KeyError: 'response'
<Greenlet at 0xa30f20c: simi(u'\u7ec8\u4e8e\u641e\u597d\u4e86')> failed with KeyError

Traceback (most recent call last):
  File "/home/nightwish/elfin/local/lib/python2.7/site-packages/gevent/greenlet.py", line 327, in run
    result = self._run(*self.args, **self.kwargs)
  File "/home/nightwish/elfin/scripts/simi.py", line 17, in simi
    return respons['response']
KeyError: 'response'
<Greenlet at 0xa30f20c: simi(u'\u4f46\u662f\u5c0f\u9ec4\u9e21\u5728\u54ea\u554a)> failed with KeyError

Traceback (most recent call last):
  File "/home/nightwish/elfin/local/lib/python2.7/site-packages/gevent/greenlet.py", line 327, in run
    result = self._run(*self.args, **self.kwargs)
  File "/home/nightwish/elfin/scripts/simi.py", line 17, in simi
    return respons['response']
KeyError: 'response'
<Greenlet at 0xa30f20c: simi(u'\u4e0d\u8981\u9a97\u6211 \u56fe\u7247\u53ef\u4ee)> failed with KeyError

Traceback (most recent call last):
  File "/home/nightwish/elfin/local/lib/python2.7/site-packages/gevent/greenlet.py", line 327, in run
    result = self._run(*self.args, **self.kwargs)
  File "/home/nightwish/elfin/scripts/simi.py", line 17, in simi
    return respons['response']
KeyError: 'response'
<Greenlet at 0xa30f20c: simi(u'\u4f60\u5e2e\u6211\u590d\u5236\u4e86\u4e24\u4efd)> failed with KeyError

Traceback (most recent call last):
  File "/home/nightwish/elfin/local/lib/python2.7/site-packages/gevent/greenlet.py", line 327, in run
    result = self._run(*self.args, **self.kwargs)
  File "/home/nightwish/elfin/scripts/simi.py", line 17, in simi
    return respons['response']
KeyError: 'response'
<Greenlet at 0xa30f20c: simi('Fghj')> failed with KeyError

Traceback (most recent call last):
  File "/home/nightwish/elfin/local/lib/python2.7/site-packages/gevent/greenlet.py", line 327, in run
    result = self._run(*self.args, **self.kwargs)
  File "/home/nightwish/elfin/scripts/simi.py", line 17, in simi
    return respons['response']
KeyError: 'response'
<Greenlet at 0xa30f20c: simi(u'\u6211\u8bbe\u7f6e\u4e86biu\uff5e')> failed with KeyError

Traceback (most recent call last):
  File "/home/nightwish/elfin/local/lib/python2.7/site-packages/gevent/greenlet.py", line 327, in run
    result = self._run(*self.args, **self.kwargs)
  File "/home/nightwish/elfin/scripts/simi.py", line 17, in simi
    return respons['response']
KeyError: 'response'
<Greenlet at 0xa30f20c: simi(u'\u90a3\u4f60\u4e3a\u561b\u8fd8\u662fnone\uff1f')> failed with KeyError

Traceback (most recent call last):
  File "/home/nightwish/elfin/local/lib/python2.7/site-packages/gevent/greenlet.py", line 327, in run
    result = self._run(*self.args, **self.kwargs)
  File "/home/nightwish/elfin/scripts/simi.py", line 17, in simi
    return respons['response']
KeyError: 'response'
<Greenlet at 0xa30f20c: simi(u'\u770b\u770b')> failed with KeyError

Traceback (most recent call last):
  File "/home/nightwish/elfin/local/lib/python2.7/site-packages/gevent/greenlet.py", line 327, in run
    result = self._run(*self.args, **self.kwargs)
  File "/home/nightwish/elfin/scripts/simi.py", line 17, in simi
    return respons['response']
KeyError: 'response'
<Greenlet at 0xa30f20c: simi(u'\u5c0f\u9ec4\u9e21\u5728\u54ea\u91cc')> failed with KeyError

Traceback (most recent call last):
  File "/home/nightwish/elfin/local/lib/python2.7/site-packages/gevent/greenlet.py", line 327, in run
    result = self._run(*self.args, **self.kwargs)
  File "/home/nightwish/elfin/scripts/simi.py", line 17, in simi
    return respons['response']
KeyError: 'response'
<Greenlet at 0xa30f20c: simi(u'\u8bbe\u7f6e\u4e0d\u4e86')> failed with KeyError

Traceback (most recent call last):
  File "/home/nightwish/elfin/local/lib/python2.7/site-packages/gevent/greenlet.py", line 327, in run
    result = self._run(*self.args, **self.kwargs)
  File "/home/nightwish/elfin/scripts/simi.py", line 17, in simi
    return respons['response']
KeyError: 'response'
<Greenlet at 0xa30f20c: simi('test test')> failed with KeyError

Traceback (most recent call last):
  File "/home/nightwish/elfin/local/lib/python2.7/site-packages/gevent/greenlet.py", line 327, in run
    result = self._run(*self.args, **self.kwargs)
  File "/home/nightwish/elfin/scripts/simi.py", line 17, in simi
    return respons['response']
KeyError: 'response'
<Greenlet at 0xa30fcfc: simi(u'\u5988\u86cb\u628a\u6211\u5c3e\u5df4\u7ed9\u6539)> failed with KeyError

Traceback (most recent call last):
  File "/home/nightwish/elfin/local/lib/python2.7/site-packages/gevent/greenlet.py", line 327, in run
    result = self._run(*self.args, **self.kwargs)
  File "/home/nightwish/elfin/scripts/simi.py", line 17, in simi
    return respons['response']
KeyError: 'response'
<Greenlet at 0xa30fcfc: simi(u'\u5582')> failed with KeyError

Traceback (most recent call last):
  File "/home/nightwish/elfin/local/lib/python2.7/site-packages/gevent/greenlet.py", line 327, in run
    result = self._run(*self.args, **self.kwargs)
  File "/home/nightwish/elfin/scripts/simi.py", line 17, in simi
    return respons['response']
KeyError: 'response'
<Greenlet at 0xa30fcfc: simi(u'\u4e5d\u70b9\u4e86\u3002')> failed with KeyError

Traceback (most recent call last):
  File "/home/nightwish/elfin/local/lib/python2.7/site-packages/gevent/greenlet.py", line 327, in run
    result = self._run(*self.args, **self.kwargs)
  File "/home/nightwish/elfin/scripts/simi.py", line 17, in simi
    return respons['response']
KeyError: 'response'
<Greenlet at 0xa30fcfc: simi(u'\u8036\u563f?')> failed with KeyError

Traceback (most recent call last):
  File "/home/nightwish/elfin/local/lib/python2.7/site-packages/gevent/greenlet.py", line 327, in run
    result = self._run(*self.args, **self.kwargs)
  File "/home/nightwish/elfin/scripts/simi.py", line 17, in simi
    return respons['response']
KeyError: 'response'
<Greenlet at 0xa30fcfc: simi(u'\u6539\u6210\u81ea\u5df1\u559c\u6b22\u7684\u56fa)> failed with KeyError

Traceback (most recent call last):
  File "/home/nightwish/elfin/local/lib/python2.7/site-packages/gevent/greenlet.py", line 327, in run
    result = self._run(*self.args, **self.kwargs)
  File "/home/nightwish/elfin/scripts/simi.py", line 17, in simi
    return respons['response']
KeyError: 'response'
<Greenlet at 0xa5b089c: simi(u'\u8bd5\u8bd5\u5c3e\u5df4\uff01')> failed with KeyError

Traceback (most recent call last):
  File "/home/nightwish/elfin/local/lib/python2.7/site-packages/gevent/greenlet.py", line 327, in run
    result = self._run(*self.args, **self.kwargs)
  File "/home/nightwish/elfin/scripts/simi.py", line 17, in simi
    return respons['response']
KeyError: 'response'
<Greenlet at 0x90fc20c: simi('/::)')> failed with KeyError

Traceback (most recent call last):
  File "/home/nightwish/elfin/local/lib/python2.7/site-packages/gevent/greenlet.py", line 327, in run
    result = self._run(*self.args, **self.kwargs)
  File "/home/nightwish/elfin/scripts/simi.py", line 17, in simi
    return respons['response']
KeyError: 'response'
<Greenlet at 0x90fc20c: simi('weibaSecrets')> failed with KeyError

Traceback (most recent call last):
  File "/home/nightwish/elfin/local/lib/python2.7/site-packages/gevent/greenlet.py", line 327, in run
    result = self._run(*self.args, **self.kwargs)
  File "/home/nightwish/elfin/scripts/simi.py", line 17, in simi
    return respons['response']
KeyError: 'response'
<Greenlet at 0x90fc20c: simi('/::(')> failed with KeyError

Traceback (most recent call last):
  File "/home/nightwish/elfin/local/lib/python2.7/site-packages/gevent/greenlet.py", line 327, in run
    result = self._run(*self.args, **self.kwargs)
  File "/home/nightwish/elfin/scripts/simi.py", line 17, in simi
    return respons['response']
KeyError: 'response'
<Greenlet at 0x90fc20c: simi(u'\ue40e')> failed with KeyError

Traceback (most recent call last):
  File "/home/nightwish/elfin/local/lib/python2.7/site-packages/gevent/greenlet.py", line 327, in run
    result = self._run(*self.args, **self.kwargs)
  File "/home/nightwish/elfin/scripts/simi.py", line 17, in simi
    return respons['response']
KeyError: 'response'
<Greenlet at 0x92b2acc: simi(u'\u3002\u3002\u3002')> failed with KeyError

Traceback (most recent call last):
  File "/home/nightwish/elfin/local/lib/python2.7/site-packages/gevent/greenlet.py", line 327, in run
    result = self._run(*self.args, **self.kwargs)
  File "/home/nightwish/elfin/scripts/simi.py", line 17, in simi
    return respons['response']
KeyError: 'response'
<Greenlet at 0x92b2acc: simi('/::~')> failed with KeyError

Traceback (most recent call last):
  File "/home/nightwish/elfin/local/lib/python2.7/site-packages/gevent/greenlet.py", line 327, in run
    result = self._run(*self.args, **self.kwargs)
  File "/home/nightwish/elfin/scripts/simi.py", line 17, in simi
    return respons['response']
KeyError: 'response'
<Greenlet at 0x90fc61c: simi('/::)')> failed with KeyError

Traceback (most recent call last):
  File "/home/nightwish/elfin/local/lib/python2.7/site-packages/gevent/greenlet.py", line 327, in run
    result = self._run(*self.args, **self.kwargs)
  File "/home/nightwish/elfin/scripts/simi.py", line 17, in simi
    return respons['response']
KeyError: 'response'
<Greenlet at 0x8a86d9c: simi('/::B')> failed with KeyError

Traceback (most recent call last):
  File "/home/nightwish/elfin/local/lib/python2.7/site-packages/gevent/greenlet.py", line 327, in run
    result = self._run(*self.args, **self.kwargs)
  File "/home/nightwish/elfin/scripts/simi.py", line 17, in simi
    return respons['response']
KeyError: 'response'
<Greenlet at 0xa3f7a7c: simi(u'\u8bab\u57e9 \u4e91\u5f7b\u3002')> failed with KeyError

Traceback (most recent call last):
  File "/home/nightwish/elfin/main.py", line 12, in <module>
    from handlers.wechat import wechat
  File "/home/nightwish/elfin/handlers/wechat.py", line 17, in <module>
    from scripts.mongo_operate import whether_login, del_user
  File "/home/nightwish/elfin/scripts/mongo_operate.py", line 17
    def update_user(**find_query, **update_query):
                                ^
SyntaxError: invalid syntax
Traceback (most recent call last):
  File "/home/nightwish/elfin/main.py", line 12, in <module>
    from handlers.wechat import wechat
  File "/home/nightwish/elfin/handlers/wechat.py", line 17, in <module>
    from scripts.mongo_operate import whether_login, del_user
  File "/home/nightwish/elfin/scripts/mongo_operate.py", line 17
    def update_user(**find_query, **update_query):
                                ^
SyntaxError: invalid syntax
Traceback (most recent call last):
  File "/home/nightwish/elfin/main.py", line 12, in <module>
    from handlers.wechat import wechat
  File "/home/nightwish/elfin/handlers/wechat.py", line 17, in <module>
    from scripts.mongo_operate import whether_login, del_user
  File "/home/nightwish/elfin/scripts/mongo_operate.py", line 17
    def update_user(**find_query, **update_query):
                                ^
SyntaxError: invalid syntax
Traceback (most recent call last):
  File "/home/nightwish/elfin/main.py", line 12, in <module>
    from handlers.wechat import wechat
  File "/home/nightwish/elfin/handlers/wechat.py", line 17, in <module>
    from scripts.mongo_operate import whether_login, del_user
  File "/home/nightwish/elfin/scripts/mongo_operate.py", line 17
    def update_user(**find_query, **update_query):
                                ^
SyntaxError: invalid syntax
Traceback (most recent call last):
  File "/home/nightwish/elfin/main.py", line 12, in <module>
    from handlers.wechat import wechat
  File "/home/nightwish/elfin/handlers/wechat.py", line 22, in <module>
    from scripts.openline_get import hot_word
  File "/home/nightwish/elfin/scripts/openline_get.py", line 11, in <module>
    session = pickle.loads(get_user_value('session', id=47637))
  File "/usr/lib/python2.7/pickle.py", line 1381, in loads
    file = StringIO(str)
TypeError: expected read buffer, dict found
Traceback (most recent call last):
  File "/home/nightwish/elfin/main.py", line 12, in <module>
    from handlers.wechat import wechat
  File "/home/nightwish/elfin/handlers/wechat.py", line 22, in <module>
    from scripts.openline_get import hot_word
  File "/home/nightwish/elfin/scripts/openline_get.py", line 11, in <module>
    session = pickle.loads(get_user_value('session', id=47637))
  File "/usr/lib/python2.7/pickle.py", line 1381, in loads
    file = StringIO(str)
TypeError: expected read buffer, dict found
Traceback (most recent call last):
  File "/home/nightwish/elfin/main.py", line 12, in <module>
    from handlers.wechat import wechat
  File "/home/nightwish/elfin/handlers/wechat.py", line 22, in <module>
    from scripts.openline_get import hot_word
  File "/home/nightwish/elfin/scripts/openline_get.py", line 11, in <module>
    session = pickle.loads(get_user_value('session', id=47637))
  File "/usr/lib/python2.7/pickle.py", line 1381, in loads
    file = StringIO(str)
TypeError: expected read buffer, dict found
Traceback (most recent call last):
  File "/home/nightwish/elfin/main.py", line 12, in <module>
    from handlers.wechat import wechat
  File "/home/nightwish/elfin/handlers/wechat.py", line 22, in <module>
    from scripts.openline_get import hot_word
  File "/home/nightwish/elfin/scripts/openline_get.py", line 11, in <module>
    session = pickle.loads(get_user_value('session', id=47637))
  File "/usr/lib/python2.7/pickle.py", line 1381, in loads
    file = StringIO(str)
TypeError: expected read buffer, dict found
Traceback (most recent call last):
  File "/home/nightwish/elfin/local/lib/python2.7/site-packages/gevent/greenlet.py", line 327, in run
    result = self._run(*self.args, **self.kwargs)
  File "/home/nightwish/elfin/scripts/simi.py", line 17, in simi
    return respons['response']
KeyError: 'response'
<Greenlet at 0x8f45b1c: simi(u'\u4ee5\u6c57\u6d17\u8eab\u963f\u3002')> failed with KeyError

Traceback (most recent call last):
  File "/home/nightwish/elfin/main.py", line 12, in <module>
    from handlers.wechat import wechat
  File "/home/nightwish/elfin/handlers/wechat.py", line 24, in <module>
    from scripts.message_get import get_at_num
  File "/home/nightwish/elfin/scripts/message_get.py", line 17
    user = get_user_value('wechat_id'=wechat_id)
SyntaxError: keyword can't be an expression
Traceback (most recent call last):
  File "/home/nightwish/elfin/main.py", line 12, in <module>
    from handlers.wechat import wechat
  File "/home/nightwish/elfin/handlers/wechat.py", line 24, in <module>
    from scripts.message_get import get_at_num
  File "/home/nightwish/elfin/scripts/message_get.py", line 17
    user = get_user_value('wechat_id'=wechat_id)
SyntaxError: keyword can't be an expression
Traceback (most recent call last):
  File "/home/nightwish/elfin/main.py", line 12, in <module>
    from handlers.wechat import wechat
  File "/home/nightwish/elfin/handlers/wechat.py", line 24, in <module>
    from scripts.message_get import get_at_num
  File "/home/nightwish/elfin/scripts/message_get.py", line 17
    user = get_user_value('wechat_id'=wechat_id)
SyntaxError: keyword can't be an expression
Traceback (most recent call last):
  File "/home/nightwish/elfin/main.py", line 12, in <module>
    from handlers.wechat import wechat
  File "/home/nightwish/elfin/handlers/wechat.py", line 24, in <module>
    from scripts.message_get import get_at_num
  File "/home/nightwish/elfin/scripts/message_get.py", line 17
    user = get_user_value('wechat_id'=wechat_id)
SyntaxError: keyword can't be an expression
Traceback (most recent call last):
  File "/home/nightwish/elfin/local/lib/python2.7/site-packages/gevent/greenlet.py", line 327, in run
    result = self._run(*self.args, **self.kwargs)
  File "/home/nightwish/elfin/scripts/simi.py", line 17, in simi
    return respons['response']
KeyError: 'response'
<Greenlet at 0xa2d084c: simi(u'\uc7bc\uc5c6\ub2e4')> failed with KeyError

Traceback (most recent call last):
  File "/home/nightwish/elfin/main.py", line 12, in <module>
    from handlers.wechat import wechat
  File "/home/nightwish/elfin/handlers/wechat.py", line 93
    message_num = get_message_num(message_type=key, fromUser)
SyntaxError: non-keyword arg after keyword arg
Traceback (most recent call last):
  File "/home/nightwish/elfin/main.py", line 12, in <module>
    from handlers.wechat import wechat
  File "/home/nightwish/elfin/handlers/wechat.py", line 93
    message_num = get_message_num(message_type=key, fromUser)
SyntaxError: non-keyword arg after keyword arg
Traceback (most recent call last):
  File "/home/nightwish/elfin/main.py", line 12, in <module>
    from handlers.wechat import wechat
  File "/home/nightwish/elfin/handlers/wechat.py", line 93
    message_num = get_message_num(message_type=key, fromUser)
SyntaxError: non-keyword arg after keyword arg
Traceback (most recent call last):
  File "/home/nightwish/elfin/main.py", line 12, in <module>
    from handlers.wechat import wechat
  File "/home/nightwish/elfin/handlers/wechat.py", line 93
    message_num = get_message_num(message_type=key, fromUser)
SyntaxError: non-keyword arg after keyword arg
Traceback (most recent call last):
  File "/home/nightwish/elfin/local/lib/python2.7/site-packages/gevent/greenlet.py", line 327, in run
    result = self._run(*self.args, **self.kwargs)
  File "/home/nightwish/elfin/scripts/simi.py", line 17, in simi
    return respons['response']
KeyError: 'response'
<Greenlet at 0x9717cac: simi(u'\u7f9e\u6bdb')> failed with KeyError

Traceback (most recent call last):
  File "/home/nightwish/elfin/scripts/get_access_token.py", line 40, in <module>
    get_access_token()
  File "/home/nightwish/elfin/scripts/get_access_token.py", line 29, in get_access_token
    r = requests.get(URL, params=params)
  File "/home/nightwish/elfin/local/lib/python2.7/site-packages/requests-2.2.1-py2.7.egg/requests/api.py", line 55, in get
    return request('get', url, **kwargs)
  File "/home/nightwish/elfin/local/lib/python2.7/site-packages/requests-2.2.1-py2.7.egg/requests/api.py", line 44, in request
    return session.request(method=method, url=url, **kwargs)
  File "/home/nightwish/elfin/local/lib/python2.7/site-packages/requests-2.2.1-py2.7.egg/requests/sessions.py", line 383, in request
    resp = self.send(prep, **send_kwargs)
  File "/home/nightwish/elfin/local/lib/python2.7/site-packages/requests-2.2.1-py2.7.egg/requests/sessions.py", line 486, in send
    r = adapter.send(request, **kwargs)
  File "/home/nightwish/elfin/local/lib/python2.7/site-packages/requests-2.2.1-py2.7.egg/requests/adapters.py", line 378, in send
    raise ConnectionError(e)
requests.exceptions.ConnectionError: HTTPSConnectionPool(host='api.weixin.qq.com', port=443): Max retries exceeded with url: /cgi-bin/token?secret=37e8ff0ffbe0cfa1589787cb42ab3b54&grant_type=client_credential&appid=wx16b6a22daa10d5c1 (Caused by <class 'socket.error'>: [Errno 110] Connection timed out)
Traceback (most recent call last):
  File "/home/nightwish/elfin/scripts/get_access_token.py", line 40, in <module>
    get_access_token()
  File "/home/nightwish/elfin/scripts/get_access_token.py", line 29, in get_access_token
    r = requests.get(URL, params=params)
  File "/home/nightwish/elfin/local/lib/python2.7/site-packages/requests-2.2.1-py2.7.egg/requests/api.py", line 55, in get
    return request('get', url, **kwargs)
  File "/home/nightwish/elfin/local/lib/python2.7/site-packages/requests-2.2.1-py2.7.egg/requests/api.py", line 44, in request
    return session.request(method=method, url=url, **kwargs)
  File "/home/nightwish/elfin/local/lib/python2.7/site-packages/requests-2.2.1-py2.7.egg/requests/sessions.py", line 383, in request
    resp = self.send(prep, **send_kwargs)
  File "/home/nightwish/elfin/local/lib/python2.7/site-packages/requests-2.2.1-py2.7.egg/requests/sessions.py", line 486, in send
    r = adapter.send(request, **kwargs)
  File "/home/nightwish/elfin/local/lib/python2.7/site-packages/requests-2.2.1-py2.7.egg/requests/adapters.py", line 378, in send
    raise ConnectionError(e)
requests.exceptions.ConnectionError: HTTPSConnectionPool(host='api.weixin.qq.com', port=443): Max retries exceeded with url: /cgi-bin/token?secret=37e8ff0ffbe0cfa1589787cb42ab3b54&grant_type=client_credential&appid=wx16b6a22daa10d5c1 (Caused by <class 'socket.error'>: [Errno 110] Connection timed out)
Traceback (most recent call last):
  File "/home/nightwish/elfin/scripts/get_access_token.py", line 40, in <module>
    get_access_token()
  File "/home/nightwish/elfin/scripts/get_access_token.py", line 29, in get_access_token
    r = requests.get(URL, params=params)
  File "/home/nightwish/elfin/local/lib/python2.7/site-packages/requests-2.2.1-py2.7.egg/requests/api.py", line 55, in get
    return request('get', url, **kwargs)
  File "/home/nightwish/elfin/local/lib/python2.7/site-packages/requests-2.2.1-py2.7.egg/requests/api.py", line 44, in request
    return session.request(method=method, url=url, **kwargs)
  File "/home/nightwish/elfin/local/lib/python2.7/site-packages/requests-2.2.1-py2.7.egg/requests/sessions.py", line 383, in request
    resp = self.send(prep, **send_kwargs)
  File "/home/nightwish/elfin/local/lib/python2.7/site-packages/requests-2.2.1-py2.7.egg/requests/sessions.py", line 486, in send
    r = adapter.send(request, **kwargs)
  File "/home/nightwish/elfin/local/lib/python2.7/site-packages/requests-2.2.1-py2.7.egg/requests/adapters.py", line 378, in send
    raise ConnectionError(e)
requests.exceptions.ConnectionError: HTTPSConnectionPool(host='api.weixin.qq.com', port=443): Max retries exceeded with url: /cgi-bin/token?secret=37e8ff0ffbe0cfa1589787cb42ab3b54&grant_type=client_credential&appid=wx16b6a22daa10d5c1 (Caused by <class 'socket.error'>: [Errno 110] Connection timed out)
Traceback (most recent call last):
  File "/home/nightwish/elfin/scripts/get_access_token.py", line 40, in <module>
    get_access_token()
  File "/home/nightwish/elfin/scripts/get_access_token.py", line 29, in get_access_token
    r = requests.get(URL, params=params)
  File "/home/nightwish/elfin/local/lib/python2.7/site-packages/requests-2.2.1-py2.7.egg/requests/api.py", line 55, in get
    return request('get', url, **kwargs)
  File "/home/nightwish/elfin/local/lib/python2.7/site-packages/requests-2.2.1-py2.7.egg/requests/api.py", line 44, in request
    return session.request(method=method, url=url, **kwargs)
  File "/home/nightwish/elfin/local/lib/python2.7/site-packages/requests-2.2.1-py2.7.egg/requests/sessions.py", line 383, in request
    resp = self.send(prep, **send_kwargs)
  File "/home/nightwish/elfin/local/lib/python2.7/site-packages/requests-2.2.1-py2.7.egg/requests/sessions.py", line 486, in send
    r = adapter.send(request, **kwargs)
  File "/home/nightwish/elfin/local/lib/python2.7/site-packages/requests-2.2.1-py2.7.egg/requests/adapters.py", line 378, in send
    raise ConnectionError(e)
requests.exceptions.ConnectionError: HTTPSConnectionPool(host='api.weixin.qq.com', port=443): Max retries exceeded with url: /cgi-bin/token?secret=37e8ff0ffbe0cfa1589787cb42ab3b54&grant_type=client_credential&appid=wx16b6a22daa10d5c1 (Caused by <class 'socket.error'>: [Errno 110] Connection timed out)
Traceback (most recent call last):
  File "/home/nightwish/elfin/scripts/get_access_token.py", line 40, in <module>
    get_access_token()
  File "/home/nightwish/elfin/scripts/get_access_token.py", line 29, in get_access_token
    r = requests.get(URL, params=params)
  File "/home/nightwish/elfin/local/lib/python2.7/site-packages/requests-2.2.1-py2.7.egg/requests/api.py", line 55, in get
    return request('get', url, **kwargs)
  File "/home/nightwish/elfin/local/lib/python2.7/site-packages/requests-2.2.1-py2.7.egg/requests/api.py", line 44, in request
    return session.request(method=method, url=url, **kwargs)
  File "/home/nightwish/elfin/local/lib/python2.7/site-packages/requests-2.2.1-py2.7.egg/requests/sessions.py", line 383, in request
    resp = self.send(prep, **send_kwargs)
  File "/home/nightwish/elfin/local/lib/python2.7/site-packages/requests-2.2.1-py2.7.egg/requests/sessions.py", line 486, in send
    r = adapter.send(request, **kwargs)
  File "/home/nightwish/elfin/local/lib/python2.7/site-packages/requests-2.2.1-py2.7.egg/requests/adapters.py", line 378, in send
    raise ConnectionError(e)
requests.exceptions.ConnectionError: HTTPSConnectionPool(host='api.weixin.qq.com', port=443): Max retries exceeded with url: /cgi-bin/token?secret=37e8ff0ffbe0cfa1589787cb42ab3b54&grant_type=client_credential&appid=wx16b6a22daa10d5c1 (Caused by <class 'socket.error'>: [Errno 110] Connection timed out)
Traceback (most recent call last):
  File "/home/nightwish/elfin/scripts/get_access_token.py", line 40, in <module>
    get_access_token()
  File "/home/nightwish/elfin/scripts/get_access_token.py", line 29, in get_access_token
    r = requests.get(URL, params=params)
  File "/home/nightwish/elfin/local/lib/python2.7/site-packages/requests-2.2.1-py2.7.egg/requests/api.py", line 55, in get
    return request('get', url, **kwargs)
  File "/home/nightwish/elfin/local/lib/python2.7/site-packages/requests-2.2.1-py2.7.egg/requests/api.py", line 44, in request
    return session.request(method=method, url=url, **kwargs)
  File "/home/nightwish/elfin/local/lib/python2.7/site-packages/requests-2.2.1-py2.7.egg/requests/sessions.py", line 383, in request
    resp = self.send(prep, **send_kwargs)
  File "/home/nightwish/elfin/local/lib/python2.7/site-packages/requests-2.2.1-py2.7.egg/requests/sessions.py", line 486, in send
    r = adapter.send(request, **kwargs)
  File "/home/nightwish/elfin/local/lib/python2.7/site-packages/requests-2.2.1-py2.7.egg/requests/adapters.py", line 378, in send
    raise ConnectionError(e)
requests.exceptions.ConnectionError: HTTPSConnectionPool(host='api.weixin.qq.com', port=443): Max retries exceeded with url: /cgi-bin/token?secret=37e8ff0ffbe0cfa1589787cb42ab3b54&grant_type=client_credential&appid=wx16b6a22daa10d5c1 (Caused by <class 'socket.error'>: [Errno 110] Connection timed out)
Traceback (most recent call last):
  File "/home/nightwish/elfin/scripts/get_access_token.py", line 40, in <module>
    get_access_token()
  File "/home/nightwish/elfin/scripts/get_access_token.py", line 29, in get_access_token
    r = requests.get(URL, params=params)
  File "/home/nightwish/elfin/local/lib/python2.7/site-packages/requests-2.2.1-py2.7.egg/requests/api.py", line 55, in get
    return request('get', url, **kwargs)
  File "/home/nightwish/elfin/local/lib/python2.7/site-packages/requests-2.2.1-py2.7.egg/requests/api.py", line 44, in request
    return session.request(method=method, url=url, **kwargs)
  File "/home/nightwish/elfin/local/lib/python2.7/site-packages/requests-2.2.1-py2.7.egg/requests/sessions.py", line 383, in request
    resp = self.send(prep, **send_kwargs)
  File "/home/nightwish/elfin/local/lib/python2.7/site-packages/requests-2.2.1-py2.7.egg/requests/sessions.py", line 486, in send
    r = adapter.send(request, **kwargs)
  File "/home/nightwish/elfin/local/lib/python2.7/site-packages/requests-2.2.1-py2.7.egg/requests/adapters.py", line 378, in send
    raise ConnectionError(e)
requests.exceptions.ConnectionError: HTTPSConnectionPool(host='api.weixin.qq.com', port=443): Max retries exceeded with url: /cgi-bin/token?secret=37e8ff0ffbe0cfa1589787cb42ab3b54&grant_type=client_credential&appid=wx16b6a22daa10d5c1 (Caused by <class 'socket.error'>: [Errno 110] Connection timed out)
Traceback (most recent call last):
  File "/home/nightwish/elfin/scripts/get_access_token.py", line 40, in <module>
    get_access_token()
  File "/home/nightwish/elfin/scripts/get_access_token.py", line 29, in get_access_token
    r = requests.get(URL, params=params)
  File "/home/nightwish/elfin/local/lib/python2.7/site-packages/requests-2.2.1-py2.7.egg/requests/api.py", line 55, in get
    return request('get', url, **kwargs)
  File "/home/nightwish/elfin/local/lib/python2.7/site-packages/requests-2.2.1-py2.7.egg/requests/api.py", line 44, in request
    return session.request(method=method, url=url, **kwargs)
  File "/home/nightwish/elfin/local/lib/python2.7/site-packages/requests-2.2.1-py2.7.egg/requests/sessions.py", line 383, in request
    resp = self.send(prep, **send_kwargs)
  File "/home/nightwish/elfin/local/lib/python2.7/site-packages/requests-2.2.1-py2.7.egg/requests/sessions.py", line 486, in send
    r = adapter.send(request, **kwargs)
  File "/home/nightwish/elfin/local/lib/python2.7/site-packages/requests-2.2.1-py2.7.egg/requests/adapters.py", line 378, in send
    raise ConnectionError(e)
requests.exceptions.ConnectionError: HTTPSConnectionPool(host='api.weixin.qq.com', port=443): Max retries exceeded with url: /cgi-bin/token?secret=37e8ff0ffbe0cfa1589787cb42ab3b54&grant_type=client_credential&appid=wx16b6a22daa10d5c1 (Caused by <class 'socket.error'>: [Errno 110] Connection timed out)
Traceback (most recent call last):
  File "/home/nightwish/elfin/scripts/get_access_token.py", line 40, in <module>
    get_access_token()
  File "/home/nightwish/elfin/scripts/get_access_token.py", line 29, in get_access_token
    r = requests.get(URL, params=params)
  File "/home/nightwish/elfin/local/lib/python2.7/site-packages/requests-2.2.1-py2.7.egg/requests/api.py", line 55, in get
    return request('get', url, **kwargs)
  File "/home/nightwish/elfin/local/lib/python2.7/site-packages/requests-2.2.1-py2.7.egg/requests/api.py", line 44, in request
    return session.request(method=method, url=url, **kwargs)
  File "/home/nightwish/elfin/local/lib/python2.7/site-packages/requests-2.2.1-py2.7.egg/requests/sessions.py", line 383, in request
    resp = self.send(prep, **send_kwargs)
  File "/home/nightwish/elfin/local/lib/python2.7/site-packages/requests-2.2.1-py2.7.egg/requests/sessions.py", line 486, in send
    r = adapter.send(request, **kwargs)
  File "/home/nightwish/elfin/local/lib/python2.7/site-packages/requests-2.2.1-py2.7.egg/requests/adapters.py", line 378, in send
    raise ConnectionError(e)
requests.exceptions.ConnectionError: HTTPSConnectionPool(host='api.weixin.qq.com', port=443): Max retries exceeded with url: /cgi-bin/token?secret=37e8ff0ffbe0cfa1589787cb42ab3b54&grant_type=client_credential&appid=wx16b6a22daa10d5c1 (Caused by <class 'socket.error'>: [Errno 110] Connection timed out)
Traceback (most recent call last):
  File "/home/nightwish/elfin/scripts/get_access_token.py", line 40, in <module>
    get_access_token()
  File "/home/nightwish/elfin/scripts/get_access_token.py", line 29, in get_access_token
    r = requests.get(URL, params=params)
  File "/home/nightwish/elfin/local/lib/python2.7/site-packages/requests-2.2.1-py2.7.egg/requests/api.py", line 55, in get
    return request('get', url, **kwargs)
  File "/home/nightwish/elfin/local/lib/python2.7/site-packages/requests-2.2.1-py2.7.egg/requests/api.py", line 44, in request
    return session.request(method=method, url=url, **kwargs)
  File "/home/nightwish/elfin/local/lib/python2.7/site-packages/requests-2.2.1-py2.7.egg/requests/sessions.py", line 383, in request
    resp = self.send(prep, **send_kwargs)
  File "/home/nightwish/elfin/local/lib/python2.7/site-packages/requests-2.2.1-py2.7.egg/requests/sessions.py", line 486, in send
    r = adapter.send(request, **kwargs)
  File "/home/nightwish/elfin/local/lib/python2.7/site-packages/requests-2.2.1-py2.7.egg/requests/adapters.py", line 378, in send
    raise ConnectionError(e)
requests.exceptions.ConnectionError: HTTPSConnectionPool(host='api.weixin.qq.com', port=443): Max retries exceeded with url: /cgi-bin/token?secret=37e8ff0ffbe0cfa1589787cb42ab3b54&grant_type=client_credential&appid=wx16b6a22daa10d5c1 (Caused by <class 'socket.error'>: [Errno 110] Connection timed out)
Traceback (most recent call last):
  File "/home/nightwish/elfin/scripts/get_access_token.py", line 40, in <module>
    get_access_token()
  File "/home/nightwish/elfin/scripts/get_access_token.py", line 29, in get_access_token
    r = requests.get(URL, params=params)
  File "/home/nightwish/elfin/local/lib/python2.7/site-packages/requests-2.2.1-py2.7.egg/requests/api.py", line 55, in get
    return request('get', url, **kwargs)
  File "/home/nightwish/elfin/local/lib/python2.7/site-packages/requests-2.2.1-py2.7.egg/requests/api.py", line 44, in request
    return session.request(method=method, url=url, **kwargs)
  File "/home/nightwish/elfin/local/lib/python2.7/site-packages/requests-2.2.1-py2.7.egg/requests/sessions.py", line 383, in request
    resp = self.send(prep, **send_kwargs)
  File "/home/nightwish/elfin/local/lib/python2.7/site-packages/requests-2.2.1-py2.7.egg/requests/sessions.py", line 486, in send
    r = adapter.send(request, **kwargs)
  File "/home/nightwish/elfin/local/lib/python2.7/site-packages/requests-2.2.1-py2.7.egg/requests/adapters.py", line 378, in send
    raise ConnectionError(e)
requests.exceptions.ConnectionError: HTTPSConnectionPool(host='api.weixin.qq.com', port=443): Max retries exceeded with url: /cgi-bin/token?secret=37e8ff0ffbe0cfa1589787cb42ab3b54&grant_type=client_credential&appid=wx16b6a22daa10d5c1 (Caused by <class 'socket.error'>: [Errno 110] Connection timed out)
Traceback (most recent call last):
  File "/home/nightwish/elfin/scripts/get_access_token.py", line 40, in <module>
    get_access_token()
  File "/home/nightwish/elfin/scripts/get_access_token.py", line 29, in get_access_token
    r = requests.get(URL, params=params)
  File "/home/nightwish/elfin/local/lib/python2.7/site-packages/requests-2.2.1-py2.7.egg/requests/api.py", line 55, in get
    return request('get', url, **kwargs)
  File "/home/nightwish/elfin/local/lib/python2.7/site-packages/requests-2.2.1-py2.7.egg/requests/api.py", line 44, in request
    return session.request(method=method, url=url, **kwargs)
  File "/home/nightwish/elfin/local/lib/python2.7/site-packages/requests-2.2.1-py2.7.egg/requests/sessions.py", line 383, in request
    resp = self.send(prep, **send_kwargs)
  File "/home/nightwish/elfin/local/lib/python2.7/site-packages/requests-2.2.1-py2.7.egg/requests/sessions.py", line 486, in send
    r = adapter.send(request, **kwargs)
  File "/home/nightwish/elfin/local/lib/python2.7/site-packages/requests-2.2.1-py2.7.egg/requests/adapters.py", line 378, in send
    raise ConnectionError(e)
requests.exceptions.ConnectionError: HTTPSConnectionPool(host='api.weixin.qq.com', port=443): Max retries exceeded with url: /cgi-bin/token?secret=37e8ff0ffbe0cfa1589787cb42ab3b54&grant_type=client_credential&appid=wx16b6a22daa10d5c1 (Caused by <class 'socket.error'>: [Errno 110] Connection timed out)
Traceback (most recent call last):
  File "/home/nightwish/elfin/scripts/get_access_token.py", line 40, in <module>
    get_access_token()
  File "/home/nightwish/elfin/scripts/get_access_token.py", line 29, in get_access_token
    r = requests.get(URL, params=params)
  File "/home/nightwish/elfin/local/lib/python2.7/site-packages/requests-2.2.1-py2.7.egg/requests/api.py", line 55, in get
    return request('get', url, **kwargs)
  File "/home/nightwish/elfin/local/lib/python2.7/site-packages/requests-2.2.1-py2.7.egg/requests/api.py", line 44, in request
    return session.request(method=method, url=url, **kwargs)
  File "/home/nightwish/elfin/local/lib/python2.7/site-packages/requests-2.2.1-py2.7.egg/requests/sessions.py", line 383, in request
    resp = self.send(prep, **send_kwargs)
  File "/home/nightwish/elfin/local/lib/python2.7/site-packages/requests-2.2.1-py2.7.egg/requests/sessions.py", line 486, in send
    r = adapter.send(request, **kwargs)
  File "/home/nightwish/elfin/local/lib/python2.7/site-packages/requests-2.2.1-py2.7.egg/requests/adapters.py", line 378, in send
    raise ConnectionError(e)
requests.exceptions.ConnectionError: HTTPSConnectionPool(host='api.weixin.qq.com', port=443): Max retries exceeded with url: /cgi-bin/token?secret=37e8ff0ffbe0cfa1589787cb42ab3b54&grant_type=client_credential&appid=wx16b6a22daa10d5c1 (Caused by <class 'socket.error'>: [Errno 110] Connection timed out)
Traceback (most recent call last):
  File "/home/nightwish/elfin/scripts/get_access_token.py", line 40, in <module>
    get_access_token()
  File "/home/nightwish/elfin/scripts/get_access_token.py", line 29, in get_access_token
    r = requests.get(URL, params=params)
  File "/home/nightwish/elfin/local/lib/python2.7/site-packages/requests-2.2.1-py2.7.egg/requests/api.py", line 55, in get
    return request('get', url, **kwargs)
  File "/home/nightwish/elfin/local/lib/python2.7/site-packages/requests-2.2.1-py2.7.egg/requests/api.py", line 44, in request
    return session.request(method=method, url=url, **kwargs)
  File "/home/nightwish/elfin/local/lib/python2.7/site-packages/requests-2.2.1-py2.7.egg/requests/sessions.py", line 383, in request
    resp = self.send(prep, **send_kwargs)
  File "/home/nightwish/elfin/local/lib/python2.7/site-packages/requests-2.2.1-py2.7.egg/requests/sessions.py", line 486, in send
    r = adapter.send(request, **kwargs)
  File "/home/nightwish/elfin/local/lib/python2.7/site-packages/requests-2.2.1-py2.7.egg/requests/adapters.py", line 378, in send
    raise ConnectionError(e)
requests.exceptions.ConnectionError: HTTPSConnectionPool(host='api.weixin.qq.com', port=443): Max retries exceeded with url: /cgi-bin/token?secret=37e8ff0ffbe0cfa1589787cb42ab3b54&grant_type=client_credential&appid=wx16b6a22daa10d5c1 (Caused by <class 'socket.error'>: [Errno 110] Connection timed out)
Traceback (most recent call last):
  File "/home/nightwish/elfin/scripts/get_access_token.py", line 40, in <module>
    get_access_token()
  File "/home/nightwish/elfin/scripts/get_access_token.py", line 29, in get_access_token
    r = requests.get(URL, params=params)
  File "/home/nightwish/elfin/local/lib/python2.7/site-packages/requests-2.2.1-py2.7.egg/requests/api.py", line 55, in get
    return request('get', url, **kwargs)
  File "/home/nightwish/elfin/local/lib/python2.7/site-packages/requests-2.2.1-py2.7.egg/requests/api.py", line 44, in request
    return session.request(method=method, url=url, **kwargs)
  File "/home/nightwish/elfin/local/lib/python2.7/site-packages/requests-2.2.1-py2.7.egg/requests/sessions.py", line 383, in request
    resp = self.send(prep, **send_kwargs)
  File "/home/nightwish/elfin/local/lib/python2.7/site-packages/requests-2.2.1-py2.7.egg/requests/sessions.py", line 486, in send
    r = adapter.send(request, **kwargs)
  File "/home/nightwish/elfin/local/lib/python2.7/site-packages/requests-2.2.1-py2.7.egg/requests/adapters.py", line 378, in send
    raise ConnectionError(e)
requests.exceptions.ConnectionError: HTTPSConnectionPool(host='api.weixin.qq.com', port=443): Max retries exceeded with url: /cgi-bin/token?secret=37e8ff0ffbe0cfa1589787cb42ab3b54&grant_type=client_credential&appid=wx16b6a22daa10d5c1 (Caused by <class 'socket.error'>: [Errno 110] Connection timed out)
Traceback (most recent call last):
  File "/home/nightwish/elfin/scripts/get_access_token.py", line 40, in <module>
    get_access_token()
  File "/home/nightwish/elfin/scripts/get_access_token.py", line 29, in get_access_token
    r = requests.get(URL, params=params)
  File "/home/nightwish/elfin/local/lib/python2.7/site-packages/requests-2.2.1-py2.7.egg/requests/api.py", line 55, in get
    return request('get', url, **kwargs)
  File "/home/nightwish/elfin/local/lib/python2.7/site-packages/requests-2.2.1-py2.7.egg/requests/api.py", line 44, in request
    return session.request(method=method, url=url, **kwargs)
  File "/home/nightwish/elfin/local/lib/python2.7/site-packages/requests-2.2.1-py2.7.egg/requests/sessions.py", line 383, in request
    resp = self.send(prep, **send_kwargs)
  File "/home/nightwish/elfin/local/lib/python2.7/site-packages/requests-2.2.1-py2.7.egg/requests/sessions.py", line 486, in send
    r = adapter.send(request, **kwargs)
  File "/home/nightwish/elfin/local/lib/python2.7/site-packages/requests-2.2.1-py2.7.egg/requests/adapters.py", line 378, in send
    raise ConnectionError(e)
requests.exceptions.ConnectionError: HTTPSConnectionPool(host='api.weixin.qq.com', port=443): Max retries exceeded with url: /cgi-bin/token?secret=37e8ff0ffbe0cfa1589787cb42ab3b54&grant_type=client_credential&appid=wx16b6a22daa10d5c1 (Caused by <class 'socket.error'>: [Errno 110] Connection timed out)
Traceback (most recent call last):
  File "/home/nightwish/elfin/scripts/get_access_token.py", line 40, in <module>
    get_access_token()
  File "/home/nightwish/elfin/scripts/get_access_token.py", line 29, in get_access_token
    r = requests.get(URL, params=params)
  File "/home/nightwish/elfin/local/lib/python2.7/site-packages/requests-2.2.1-py2.7.egg/requests/api.py", line 55, in get
    return request('get', url, **kwargs)
  File "/home/nightwish/elfin/local/lib/python2.7/site-packages/requests-2.2.1-py2.7.egg/requests/api.py", line 44, in request
    return session.request(method=method, url=url, **kwargs)
  File "/home/nightwish/elfin/local/lib/python2.7/site-packages/requests-2.2.1-py2.7.egg/requests/sessions.py", line 383, in request
    resp = self.send(prep, **send_kwargs)
  File "/home/nightwish/elfin/local/lib/python2.7/site-packages/requests-2.2.1-py2.7.egg/requests/sessions.py", line 486, in send
    r = adapter.send(request, **kwargs)
  File "/home/nightwish/elfin/local/lib/python2.7/site-packages/requests-2.2.1-py2.7.egg/requests/adapters.py", line 378, in send
    raise ConnectionError(e)
requests.exceptions.ConnectionError: HTTPSConnectionPool(host='api.weixin.qq.com', port=443): Max retries exceeded with url: /cgi-bin/token?secret=37e8ff0ffbe0cfa1589787cb42ab3b54&grant_type=client_credential&appid=wx16b6a22daa10d5c1 (Caused by <class 'socket.error'>: [Errno 110] Connection timed out)
Traceback (most recent call last):
  File "/home/nightwish/elfin/scripts/get_access_token.py", line 40, in <module>
    get_access_token()
  File "/home/nightwish/elfin/scripts/get_access_token.py", line 29, in get_access_token
    r = requests.get(URL, params=params)
  File "/home/nightwish/elfin/local/lib/python2.7/site-packages/requests-2.2.1-py2.7.egg/requests/api.py", line 55, in get
    return request('get', url, **kwargs)
  File "/home/nightwish/elfin/local/lib/python2.7/site-packages/requests-2.2.1-py2.7.egg/requests/api.py", line 44, in request
    return session.request(method=method, url=url, **kwargs)
  File "/home/nightwish/elfin/local/lib/python2.7/site-packages/requests-2.2.1-py2.7.egg/requests/sessions.py", line 383, in request
    resp = self.send(prep, **send_kwargs)
  File "/home/nightwish/elfin/local/lib/python2.7/site-packages/requests-2.2.1-py2.7.egg/requests/sessions.py", line 486, in send
    r = adapter.send(request, **kwargs)
  File "/home/nightwish/elfin/local/lib/python2.7/site-packages/requests-2.2.1-py2.7.egg/requests/adapters.py", line 378, in send
    raise ConnectionError(e)
requests.exceptions.ConnectionError: HTTPSConnectionPool(host='api.weixin.qq.com', port=443): Max retries exceeded with url: /cgi-bin/token?secret=37e8ff0ffbe0cfa1589787cb42ab3b54&grant_type=client_credential&appid=wx16b6a22daa10d5c1 (Caused by <class 'socket.error'>: [Errno 110] Connection timed out)
Traceback (most recent call last):
  File "/home/nightwish/elfin/scripts/get_access_token.py", line 40, in <module>
    get_access_token()
  File "/home/nightwish/elfin/scripts/get_access_token.py", line 29, in get_access_token
    r = requests.get(URL, params=params)
  File "/home/nightwish/elfin/local/lib/python2.7/site-packages/requests-2.2.1-py2.7.egg/requests/api.py", line 55, in get
    return request('get', url, **kwargs)
  File "/home/nightwish/elfin/local/lib/python2.7/site-packages/requests-2.2.1-py2.7.egg/requests/api.py", line 44, in request
    return session.request(method=method, url=url, **kwargs)
  File "/home/nightwish/elfin/local/lib/python2.7/site-packages/requests-2.2.1-py2.7.egg/requests/sessions.py", line 383, in request
    resp = self.send(prep, **send_kwargs)
  File "/home/nightwish/elfin/local/lib/python2.7/site-packages/requests-2.2.1-py2.7.egg/requests/sessions.py", line 486, in send
    r = adapter.send(request, **kwargs)
  File "/home/nightwish/elfin/local/lib/python2.7/site-packages/requests-2.2.1-py2.7.egg/requests/adapters.py", line 378, in send
    raise ConnectionError(e)
requests.exceptions.ConnectionError: HTTPSConnectionPool(host='api.weixin.qq.com', port=443): Max retries exceeded with url: /cgi-bin/token?secret=37e8ff0ffbe0cfa1589787cb42ab3b54&grant_type=client_credential&appid=wx16b6a22daa10d5c1 (Caused by <class 'socket.error'>: [Errno 110] Connection timed out)
Traceback (most recent call last):
  File "/home/nightwish/elfin/scripts/get_access_token.py", line 40, in <module>
    get_access_token()
  File "/home/nightwish/elfin/scripts/get_access_token.py", line 29, in get_access_token
    r = requests.get(URL, params=params)
  File "/home/nightwish/elfin/local/lib/python2.7/site-packages/requests-2.2.1-py2.7.egg/requests/api.py", line 55, in get
    return request('get', url, **kwargs)
  File "/home/nightwish/elfin/local/lib/python2.7/site-packages/requests-2.2.1-py2.7.egg/requests/api.py", line 44, in request
    return session.request(method=method, url=url, **kwargs)
  File "/home/nightwish/elfin/local/lib/python2.7/site-packages/requests-2.2.1-py2.7.egg/requests/sessions.py", line 383, in request
    resp = self.send(prep, **send_kwargs)
  File "/home/nightwish/elfin/local/lib/python2.7/site-packages/requests-2.2.1-py2.7.egg/requests/sessions.py", line 486, in send
    r = adapter.send(request, **kwargs)
  File "/home/nightwish/elfin/local/lib/python2.7/site-packages/requests-2.2.1-py2.7.egg/requests/adapters.py", line 378, in send
    raise ConnectionError(e)
requests.exceptions.ConnectionError: HTTPSConnectionPool(host='api.weixin.qq.com', port=443): Max retries exceeded with url: /cgi-bin/token?secret=37e8ff0ffbe0cfa1589787cb42ab3b54&grant_type=client_credential&appid=wx16b6a22daa10d5c1 (Caused by <class 'socket.error'>: [Errno 110] Connection timed out)
Traceback (most recent call last):
  File "/home/nightwish/elfin/scripts/get_access_token.py", line 40, in <module>
    get_access_token()
  File "/home/nightwish/elfin/scripts/get_access_token.py", line 29, in get_access_token
    r = requests.get(URL, params=params)
  File "/home/nightwish/elfin/local/lib/python2.7/site-packages/requests-2.2.1-py2.7.egg/requests/api.py", line 55, in get
    return request('get', url, **kwargs)
  File "/home/nightwish/elfin/local/lib/python2.7/site-packages/requests-2.2.1-py2.7.egg/requests/api.py", line 44, in request
    return session.request(method=method, url=url, **kwargs)
  File "/home/nightwish/elfin/local/lib/python2.7/site-packages/requests-2.2.1-py2.7.egg/requests/sessions.py", line 383, in request
    resp = self.send(prep, **send_kwargs)
  File "/home/nightwish/elfin/local/lib/python2.7/site-packages/requests-2.2.1-py2.7.egg/requests/sessions.py", line 486, in send
    r = adapter.send(request, **kwargs)
  File "/home/nightwish/elfin/local/lib/python2.7/site-packages/requests-2.2.1-py2.7.egg/requests/adapters.py", line 378, in send
    raise ConnectionError(e)
requests.exceptions.ConnectionError: HTTPSConnectionPool(host='api.weixin.qq.com', port=443): Max retries exceeded with url: /cgi-bin/token?secret=37e8ff0ffbe0cfa1589787cb42ab3b54&grant_type=client_credential&appid=wx16b6a22daa10d5c1 (Caused by <class 'socket.error'>: [Errno 110] Connection timed out)
Traceback (most recent call last):
  File "/home/nightwish/elfin/scripts/get_access_token.py", line 40, in <module>
    get_access_token()
  File "/home/nightwish/elfin/scripts/get_access_token.py", line 29, in get_access_token
    r = requests.get(URL, params=params)
  File "/home/nightwish/elfin/local/lib/python2.7/site-packages/requests-2.2.1-py2.7.egg/requests/api.py", line 55, in get
    return request('get', url, **kwargs)
  File "/home/nightwish/elfin/local/lib/python2.7/site-packages/requests-2.2.1-py2.7.egg/requests/api.py", line 44, in request
    return session.request(method=method, url=url, **kwargs)
  File "/home/nightwish/elfin/local/lib/python2.7/site-packages/requests-2.2.1-py2.7.egg/requests/sessions.py", line 383, in request
    resp = self.send(prep, **send_kwargs)
  File "/home/nightwish/elfin/local/lib/python2.7/site-packages/requests-2.2.1-py2.7.egg/requests/sessions.py", line 486, in send
    r = adapter.send(request, **kwargs)
  File "/home/nightwish/elfin/local/lib/python2.7/site-packages/requests-2.2.1-py2.7.egg/requests/adapters.py", line 378, in send
    raise ConnectionError(e)
requests.exceptions.ConnectionError: HTTPSConnectionPool(host='api.weixin.qq.com', port=443): Max retries exceeded with url: /cgi-bin/token?secret=37e8ff0ffbe0cfa1589787cb42ab3b54&grant_type=client_credential&appid=wx16b6a22daa10d5c1 (Caused by <class 'socket.error'>: [Errno 110] Connection timed out)
Traceback (most recent call last):
  File "/home/nightwish/elfin/scripts/get_access_token.py", line 40, in <module>
    get_access_token()
  File "/home/nightwish/elfin/scripts/get_access_token.py", line 29, in get_access_token
    r = requests.get(URL, params=params)
  File "/home/nightwish/elfin/local/lib/python2.7/site-packages/requests-2.2.1-py2.7.egg/requests/api.py", line 55, in get
    return request('get', url, **kwargs)
  File "/home/nightwish/elfin/local/lib/python2.7/site-packages/requests-2.2.1-py2.7.egg/requests/api.py", line 44, in request
    return session.request(method=method, url=url, **kwargs)
  File "/home/nightwish/elfin/local/lib/python2.7/site-packages/requests-2.2.1-py2.7.egg/requests/sessions.py", line 383, in request
    resp = self.send(prep, **send_kwargs)
  File "/home/nightwish/elfin/local/lib/python2.7/site-packages/requests-2.2.1-py2.7.egg/requests/sessions.py", line 486, in send
    r = adapter.send(request, **kwargs)
  File "/home/nightwish/elfin/local/lib/python2.7/site-packages/requests-2.2.1-py2.7.egg/requests/adapters.py", line 378, in send
    raise ConnectionError(e)
requests.exceptions.ConnectionError: HTTPSConnectionPool(host='api.weixin.qq.com', port=443): Max retries exceeded with url: /cgi-bin/token?secret=37e8ff0ffbe0cfa1589787cb42ab3b54&grant_type=client_credential&appid=wx16b6a22daa10d5c1 (Caused by <class 'socket.error'>: [Errno 110] Connection timed out)
Traceback (most recent call last):
  File "/home/nightwish/elfin/scripts/get_access_token.py", line 40, in <module>
    get_access_token()
  File "/home/nightwish/elfin/scripts/get_access_token.py", line 29, in get_access_token
    r = requests.get(URL, params=params)
  File "/home/nightwish/elfin/local/lib/python2.7/site-packages/requests-2.2.1-py2.7.egg/requests/api.py", line 55, in get
    return request('get', url, **kwargs)
  File "/home/nightwish/elfin/local/lib/python2.7/site-packages/requests-2.2.1-py2.7.egg/requests/api.py", line 44, in request
    return session.request(method=method, url=url, **kwargs)
  File "/home/nightwish/elfin/local/lib/python2.7/site-packages/requests-2.2.1-py2.7.egg/requests/sessions.py", line 383, in request
    resp = self.send(prep, **send_kwargs)
  File "/home/nightwish/elfin/local/lib/python2.7/site-packages/requests-2.2.1-py2.7.egg/requests/sessions.py", line 486, in send
    r = adapter.send(request, **kwargs)
  File "/home/nightwish/elfin/local/lib/python2.7/site-packages/requests-2.2.1-py2.7.egg/requests/adapters.py", line 378, in send
    raise ConnectionError(e)
requests.exceptions.ConnectionError: HTTPSConnectionPool(host='api.weixin.qq.com', port=443): Max retries exceeded with url: /cgi-bin/token?secret=37e8ff0ffbe0cfa1589787cb42ab3b54&grant_type=client_credential&appid=wx16b6a22daa10d5c1 (Caused by <class 'socket.error'>: [Errno 110] Connection timed out)
Traceback (most recent call last):
  File "/home/nightwish/elfin/scripts/get_access_token.py", line 40, in <module>
    get_access_token()
  File "/home/nightwish/elfin/scripts/get_access_token.py", line 29, in get_access_token
    r = requests.get(URL, params=params)
  File "/home/nightwish/elfin/local/lib/python2.7/site-packages/requests-2.2.1-py2.7.egg/requests/api.py", line 55, in get
    return request('get', url, **kwargs)
  File "/home/nightwish/elfin/local/lib/python2.7/site-packages/requests-2.2.1-py2.7.egg/requests/api.py", line 44, in request
    return session.request(method=method, url=url, **kwargs)
  File "/home/nightwish/elfin/local/lib/python2.7/site-packages/requests-2.2.1-py2.7.egg/requests/sessions.py", line 383, in request
    resp = self.send(prep, **send_kwargs)
  File "/home/nightwish/elfin/local/lib/python2.7/site-packages/requests-2.2.1-py2.7.egg/requests/sessions.py", line 486, in send
    r = adapter.send(request, **kwargs)
  File "/home/nightwish/elfin/local/lib/python2.7/site-packages/requests-2.2.1-py2.7.egg/requests/adapters.py", line 378, in send
    raise ConnectionError(e)
requests.exceptions.ConnectionError: HTTPSConnectionPool(host='api.weixin.qq.com', port=443): Max retries exceeded with url: /cgi-bin/token?secret=37e8ff0ffbe0cfa1589787cb42ab3b54&grant_type=client_credential&appid=wx16b6a22daa10d5c1 (Caused by <class 'socket.error'>: [Errno 110] Connection timed out)
Traceback (most recent call last):
  File "/home/nightwish/elfin/scripts/get_access_token.py", line 40, in <module>
    get_access_token()
  File "/home/nightwish/elfin/scripts/get_access_token.py", line 29, in get_access_token
    r = requests.get(URL, params=params)
  File "/home/nightwish/elfin/local/lib/python2.7/site-packages/requests-2.2.1-py2.7.egg/requests/api.py", line 55, in get
    return request('get', url, **kwargs)
  File "/home/nightwish/elfin/local/lib/python2.7/site-packages/requests-2.2.1-py2.7.egg/requests/api.py", line 44, in request
    return session.request(method=method, url=url, **kwargs)
  File "/home/nightwish/elfin/local/lib/python2.7/site-packages/requests-2.2.1-py2.7.egg/requests/sessions.py", line 383, in request
    resp = self.send(prep, **send_kwargs)
  File "/home/nightwish/elfin/local/lib/python2.7/site-packages/requests-2.2.1-py2.7.egg/requests/sessions.py", line 486, in send
    r = adapter.send(request, **kwargs)
  File "/home/nightwish/elfin/local/lib/python2.7/site-packages/requests-2.2.1-py2.7.egg/requests/adapters.py", line 378, in send
    raise ConnectionError(e)
requests.exceptions.ConnectionError: HTTPSConnectionPool(host='api.weixin.qq.com', port=443): Max retries exceeded with url: /cgi-bin/token?secret=37e8ff0ffbe0cfa1589787cb42ab3b54&grant_type=client_credential&appid=wx16b6a22daa10d5c1 (Caused by <class 'socket.error'>: [Errno 110] Connection timed out)
Traceback (most recent call last):
  File "/home/nightwish/elfin/scripts/get_access_token.py", line 40, in <module>
    get_access_token()
  File "/home/nightwish/elfin/scripts/get_access_token.py", line 29, in get_access_token
    r = requests.get(URL, params=params)
  File "/home/nightwish/elfin/local/lib/python2.7/site-packages/requests-2.2.1-py2.7.egg/requests/api.py", line 55, in get
    return request('get', url, **kwargs)
  File "/home/nightwish/elfin/local/lib/python2.7/site-packages/requests-2.2.1-py2.7.egg/requests/api.py", line 44, in request
    return session.request(method=method, url=url, **kwargs)
  File "/home/nightwish/elfin/local/lib/python2.7/site-packages/requests-2.2.1-py2.7.egg/requests/sessions.py", line 383, in request
    resp = self.send(prep, **send_kwargs)
  File "/home/nightwish/elfin/local/lib/python2.7/site-packages/requests-2.2.1-py2.7.egg/requests/sessions.py", line 486, in send
    r = adapter.send(request, **kwargs)
  File "/home/nightwish/elfin/local/lib/python2.7/site-packages/requests-2.2.1-py2.7.egg/requests/adapters.py", line 378, in send
    raise ConnectionError(e)
requests.exceptions.ConnectionError: HTTPSConnectionPool(host='api.weixin.qq.com', port=443): Max retries exceeded with url: /cgi-bin/token?secret=37e8ff0ffbe0cfa1589787cb42ab3b54&grant_type=client_credential&appid=wx16b6a22daa10d5c1 (Caused by <class 'socket.error'>: [Errno 110] Connection timed out)
Traceback (most recent call last):
  File "/home/nightwish/elfin/scripts/get_access_token.py", line 40, in <module>
    get_access_token()
  File "/home/nightwish/elfin/scripts/get_access_token.py", line 29, in get_access_token
    r = requests.get(URL, params=params)
  File "/home/nightwish/elfin/local/lib/python2.7/site-packages/requests-2.2.1-py2.7.egg/requests/api.py", line 55, in get
    return request('get', url, **kwargs)
  File "/home/nightwish/elfin/local/lib/python2.7/site-packages/requests-2.2.1-py2.7.egg/requests/api.py", line 44, in request
    return session.request(method=method, url=url, **kwargs)
  File "/home/nightwish/elfin/local/lib/python2.7/site-packages/requests-2.2.1-py2.7.egg/requests/sessions.py", line 383, in request
    resp = self.send(prep, **send_kwargs)
  File "/home/nightwish/elfin/local/lib/python2.7/site-packages/requests-2.2.1-py2.7.egg/requests/sessions.py", line 486, in send
    r = adapter.send(request, **kwargs)
  File "/home/nightwish/elfin/local/lib/python2.7/site-packages/requests-2.2.1-py2.7.egg/requests/adapters.py", line 378, in send
    raise ConnectionError(e)
requests.exceptions.ConnectionError: HTTPSConnectionPool(host='api.weixin.qq.com', port=443): Max retries exceeded with url: /cgi-bin/token?secret=37e8ff0ffbe0cfa1589787cb42ab3b54&grant_type=client_credential&appid=wx16b6a22daa10d5c1 (Caused by <class 'socket.error'>: [Errno 110] Connection timed out)
Traceback (most recent call last):
  File "/home/nightwish/elfin/scripts/get_access_token.py", line 40, in <module>
    get_access_token()
  File "/home/nightwish/elfin/scripts/get_access_token.py", line 29, in get_access_token
    r = requests.get(URL, params=params)
  File "/home/nightwish/elfin/local/lib/python2.7/site-packages/requests-2.2.1-py2.7.egg/requests/api.py", line 55, in get
    return request('get', url, **kwargs)
  File "/home/nightwish/elfin/local/lib/python2.7/site-packages/requests-2.2.1-py2.7.egg/requests/api.py", line 44, in request
    return session.request(method=method, url=url, **kwargs)
  File "/home/nightwish/elfin/local/lib/python2.7/site-packages/requests-2.2.1-py2.7.egg/requests/sessions.py", line 383, in request
    resp = self.send(prep, **send_kwargs)
  File "/home/nightwish/elfin/local/lib/python2.7/site-packages/requests-2.2.1-py2.7.egg/requests/sessions.py", line 486, in send
    r = adapter.send(request, **kwargs)
  File "/home/nightwish/elfin/local/lib/python2.7/site-packages/requests-2.2.1-py2.7.egg/requests/adapters.py", line 378, in send
    raise ConnectionError(e)
requests.exceptions.ConnectionError: HTTPSConnectionPool(host='api.weixin.qq.com', port=443): Max retries exceeded with url: /cgi-bin/token?secret=37e8ff0ffbe0cfa1589787cb42ab3b54&grant_type=client_credential&appid=wx16b6a22daa10d5c1 (Caused by <class 'socket.error'>: [Errno 110] Connection timed out)
Traceback (most recent call last):
  File "/home/nightwish/elfin/scripts/get_access_token.py", line 40, in <module>
    get_access_token()
  File "/home/nightwish/elfin/scripts/get_access_token.py", line 29, in get_access_token
    r = requests.get(URL, params=params)
  File "/home/nightwish/elfin/local/lib/python2.7/site-packages/requests-2.2.1-py2.7.egg/requests/api.py", line 55, in get
    return request('get', url, **kwargs)
  File "/home/nightwish/elfin/local/lib/python2.7/site-packages/requests-2.2.1-py2.7.egg/requests/api.py", line 44, in request
    return session.request(method=method, url=url, **kwargs)
  File "/home/nightwish/elfin/local/lib/python2.7/site-packages/requests-2.2.1-py2.7.egg/requests/sessions.py", line 383, in request
    resp = self.send(prep, **send_kwargs)
  File "/home/nightwish/elfin/local/lib/python2.7/site-packages/requests-2.2.1-py2.7.egg/requests/sessions.py", line 486, in send
    r = adapter.send(request, **kwargs)
  File "/home/nightwish/elfin/local/lib/python2.7/site-packages/requests-2.2.1-py2.7.egg/requests/adapters.py", line 378, in send
    raise ConnectionError(e)
requests.exceptions.ConnectionError: HTTPSConnectionPool(host='api.weixin.qq.com', port=443): Max retries exceeded with url: /cgi-bin/token?secret=37e8ff0ffbe0cfa1589787cb42ab3b54&grant_type=client_credential&appid=wx16b6a22daa10d5c1 (Caused by <class 'socket.error'>: [Errno 110] Connection timed out)
Traceback (most recent call last):
  File "/home/nightwish/elfin/scripts/get_access_token.py", line 40, in <module>
    get_access_token()
  File "/home/nightwish/elfin/scripts/get_access_token.py", line 29, in get_access_token
    r = requests.get(URL, params=params)
  File "/home/nightwish/elfin/local/lib/python2.7/site-packages/requests-2.2.1-py2.7.egg/requests/api.py", line 55, in get
    return request('get', url, **kwargs)
  File "/home/nightwish/elfin/local/lib/python2.7/site-packages/requests-2.2.1-py2.7.egg/requests/api.py", line 44, in request
    return session.request(method=method, url=url, **kwargs)
  File "/home/nightwish/elfin/local/lib/python2.7/site-packages/requests-2.2.1-py2.7.egg/requests/sessions.py", line 383, in request
    resp = self.send(prep, **send_kwargs)
  File "/home/nightwish/elfin/local/lib/python2.7/site-packages/requests-2.2.1-py2.7.egg/requests/sessions.py", line 486, in send
    r = adapter.send(request, **kwargs)
  File "/home/nightwish/elfin/local/lib/python2.7/site-packages/requests-2.2.1-py2.7.egg/requests/adapters.py", line 378, in send
    raise ConnectionError(e)
requests.exceptions.ConnectionError: HTTPSConnectionPool(host='api.weixin.qq.com', port=443): Max retries exceeded with url: /cgi-bin/token?secret=37e8ff0ffbe0cfa1589787cb42ab3b54&grant_type=client_credential&appid=wx16b6a22daa10d5c1 (Caused by <class 'socket.error'>: [Errno 110] Connection timed out)
Traceback (most recent call last):
  File "/home/nightwish/elfin/scripts/get_access_token.py", line 40, in <module>
    get_access_token()
  File "/home/nightwish/elfin/scripts/get_access_token.py", line 29, in get_access_token
    r = requests.get(URL, params=params)
  File "/home/nightwish/elfin/local/lib/python2.7/site-packages/requests-2.2.1-py2.7.egg/requests/api.py", line 55, in get
    return request('get', url, **kwargs)
  File "/home/nightwish/elfin/local/lib/python2.7/site-packages/requests-2.2.1-py2.7.egg/requests/api.py", line 44, in request
    return session.request(method=method, url=url, **kwargs)
  File "/home/nightwish/elfin/local/lib/python2.7/site-packages/requests-2.2.1-py2.7.egg/requests/sessions.py", line 383, in request
    resp = self.send(prep, **send_kwargs)
  File "/home/nightwish/elfin/local/lib/python2.7/site-packages/requests-2.2.1-py2.7.egg/requests/sessions.py", line 486, in send
    r = adapter.send(request, **kwargs)
  File "/home/nightwish/elfin/local/lib/python2.7/site-packages/requests-2.2.1-py2.7.egg/requests/adapters.py", line 378, in send
    raise ConnectionError(e)
requests.exceptions.ConnectionError: HTTPSConnectionPool(host='api.weixin.qq.com', port=443): Max retries exceeded with url: /cgi-bin/token?secret=37e8ff0ffbe0cfa1589787cb42ab3b54&grant_type=client_credential&appid=wx16b6a22daa10d5c1 (Caused by <class 'socket.error'>: [Errno 110] Connection timed out)
Traceback (most recent call last):
  File "/home/nightwish/elfin/scripts/get_access_token.py", line 40, in <module>
    get_access_token()
  File "/home/nightwish/elfin/scripts/get_access_token.py", line 29, in get_access_token
    r = requests.get(URL, params=params)
  File "/home/nightwish/elfin/local/lib/python2.7/site-packages/requests-2.2.1-py2.7.egg/requests/api.py", line 55, in get
    return request('get', url, **kwargs)
  File "/home/nightwish/elfin/local/lib/python2.7/site-packages/requests-2.2.1-py2.7.egg/requests/api.py", line 44, in request
    return session.request(method=method, url=url, **kwargs)
  File "/home/nightwish/elfin/local/lib/python2.7/site-packages/requests-2.2.1-py2.7.egg/requests/sessions.py", line 383, in request
    resp = self.send(prep, **send_kwargs)
  File "/home/nightwish/elfin/local/lib/python2.7/site-packages/requests-2.2.1-py2.7.egg/requests/sessions.py", line 486, in send
    r = adapter.send(request, **kwargs)
  File "/home/nightwish/elfin/local/lib/python2.7/site-packages/requests-2.2.1-py2.7.egg/requests/adapters.py", line 378, in send
    raise ConnectionError(e)
requests.exceptions.ConnectionError: HTTPSConnectionPool(host='api.weixin.qq.com', port=443): Max retries exceeded with url: /cgi-bin/token?secret=37e8ff0ffbe0cfa1589787cb42ab3b54&grant_type=client_credential&appid=wx16b6a22daa10d5c1 (Caused by <class 'socket.error'>: [Errno 110] Connection timed out)
Traceback (most recent call last):
  File "/home/nightwish/elfin/scripts/get_access_token.py", line 40, in <module>
    get_access_token()
  File "/home/nightwish/elfin/scripts/get_access_token.py", line 29, in get_access_token
    r = requests.get(URL, params=params)
  File "/home/nightwish/elfin/local/lib/python2.7/site-packages/requests-2.2.1-py2.7.egg/requests/api.py", line 55, in get
    return request('get', url, **kwargs)
  File "/home/nightwish/elfin/local/lib/python2.7/site-packages/requests-2.2.1-py2.7.egg/requests/api.py", line 44, in request
    return session.request(method=method, url=url, **kwargs)
  File "/home/nightwish/elfin/local/lib/python2.7/site-packages/requests-2.2.1-py2.7.egg/requests/sessions.py", line 383, in request
    resp = self.send(prep, **send_kwargs)
  File "/home/nightwish/elfin/local/lib/python2.7/site-packages/requests-2.2.1-py2.7.egg/requests/sessions.py", line 486, in send
    r = adapter.send(request, **kwargs)
  File "/home/nightwish/elfin/local/lib/python2.7/site-packages/requests-2.2.1-py2.7.egg/requests/adapters.py", line 378, in send
    raise ConnectionError(e)
requests.exceptions.ConnectionError: HTTPSConnectionPool(host='api.weixin.qq.com', port=443): Max retries exceeded with url: /cgi-bin/token?secret=37e8ff0ffbe0cfa1589787cb42ab3b54&grant_type=client_credential&appid=wx16b6a22daa10d5c1 (Caused by <class 'socket.error'>: [Errno 110] Connection timed out)
Traceback (most recent call last):
  File "/home/nightwish/elfin/scripts/get_access_token.py", line 40, in <module>
    get_access_token()
  File "/home/nightwish/elfin/scripts/get_access_token.py", line 29, in get_access_token
    r = requests.get(URL, params=params)
  File "/home/nightwish/elfin/local/lib/python2.7/site-packages/requests-2.2.1-py2.7.egg/requests/api.py", line 55, in get
    return request('get', url, **kwargs)
  File "/home/nightwish/elfin/local/lib/python2.7/site-packages/requests-2.2.1-py2.7.egg/requests/api.py", line 44, in request
    return session.request(method=method, url=url, **kwargs)
  File "/home/nightwish/elfin/local/lib/python2.7/site-packages/requests-2.2.1-py2.7.egg/requests/sessions.py", line 383, in request
    resp = self.send(prep, **send_kwargs)
  File "/home/nightwish/elfin/local/lib/python2.7/site-packages/requests-2.2.1-py2.7.egg/requests/sessions.py", line 486, in send
    r = adapter.send(request, **kwargs)
  File "/home/nightwish/elfin/local/lib/python2.7/site-packages/requests-2.2.1-py2.7.egg/requests/adapters.py", line 378, in send
    raise ConnectionError(e)
requests.exceptions.ConnectionError: HTTPSConnectionPool(host='api.weixin.qq.com', port=443): Max retries exceeded with url: /cgi-bin/token?secret=37e8ff0ffbe0cfa1589787cb42ab3b54&grant_type=client_credential&appid=wx16b6a22daa10d5c1 (Caused by <class 'socket.error'>: [Errno 110] Connection timed out)
Traceback (most recent call last):
  File "/home/nightwish/elfin/scripts/get_access_token.py", line 40, in <module>
    get_access_token()
  File "/home/nightwish/elfin/scripts/get_access_token.py", line 29, in get_access_token
    r = requests.get(URL, params=params)
  File "/home/nightwish/elfin/local/lib/python2.7/site-packages/requests-2.2.1-py2.7.egg/requests/api.py", line 55, in get
    return request('get', url, **kwargs)
  File "/home/nightwish/elfin/local/lib/python2.7/site-packages/requests-2.2.1-py2.7.egg/requests/api.py", line 44, in request
    return session.request(method=method, url=url, **kwargs)
  File "/home/nightwish/elfin/local/lib/python2.7/site-packages/requests-2.2.1-py2.7.egg/requests/sessions.py", line 383, in request
    resp = self.send(prep, **send_kwargs)
  File "/home/nightwish/elfin/local/lib/python2.7/site-packages/requests-2.2.1-py2.7.egg/requests/sessions.py", line 486, in send
    r = adapter.send(request, **kwargs)
  File "/home/nightwish/elfin/local/lib/python2.7/site-packages/requests-2.2.1-py2.7.egg/requests/adapters.py", line 378, in send
    raise ConnectionError(e)
requests.exceptions.ConnectionError: HTTPSConnectionPool(host='api.weixin.qq.com', port=443): Max retries exceeded with url: /cgi-bin/token?secret=37e8ff0ffbe0cfa1589787cb42ab3b54&grant_type=client_credential&appid=wx16b6a22daa10d5c1 (Caused by <class 'socket.error'>: [Errno 110] Connection timed out)
Traceback (most recent call last):
  File "/home/nightwish/elfin/scripts/get_access_token.py", line 40, in <module>
    get_access_token()
  File "/home/nightwish/elfin/scripts/get_access_token.py", line 29, in get_access_token
    r = requests.get(URL, params=params)
  File "/home/nightwish/elfin/local/lib/python2.7/site-packages/requests-2.2.1-py2.7.egg/requests/api.py", line 55, in get
    return request('get', url, **kwargs)
  File "/home/nightwish/elfin/local/lib/python2.7/site-packages/requests-2.2.1-py2.7.egg/requests/api.py", line 44, in request
    return session.request(method=method, url=url, **kwargs)
  File "/home/nightwish/elfin/local/lib/python2.7/site-packages/requests-2.2.1-py2.7.egg/requests/sessions.py", line 383, in request
    resp = self.send(prep, **send_kwargs)
  File "/home/nightwish/elfin/local/lib/python2.7/site-packages/requests-2.2.1-py2.7.egg/requests/sessions.py", line 486, in send
    r = adapter.send(request, **kwargs)
  File "/home/nightwish/elfin/local/lib/python2.7/site-packages/requests-2.2.1-py2.7.egg/requests/adapters.py", line 378, in send
    raise ConnectionError(e)
requests.exceptions.ConnectionError: HTTPSConnectionPool(host='api.weixin.qq.com', port=443): Max retries exceeded with url: /cgi-bin/token?secret=37e8ff0ffbe0cfa1589787cb42ab3b54&grant_type=client_credential&appid=wx16b6a22daa10d5c1 (Caused by <class 'socket.error'>: [Errno 110] Connection timed out)
Traceback (most recent call last):
  File "/home/nightwish/elfin/scripts/get_access_token.py", line 40, in <module>
    get_access_token()
  File "/home/nightwish/elfin/scripts/get_access_token.py", line 29, in get_access_token
    r = requests.get(URL, params=params)
  File "/home/nightwish/elfin/local/lib/python2.7/site-packages/requests-2.2.1-py2.7.egg/requests/api.py", line 55, in get
    return request('get', url, **kwargs)
  File "/home/nightwish/elfin/local/lib/python2.7/site-packages/requests-2.2.1-py2.7.egg/requests/api.py", line 44, in request
    return session.request(method=method, url=url, **kwargs)
  File "/home/nightwish/elfin/local/lib/python2.7/site-packages/requests-2.2.1-py2.7.egg/requests/sessions.py", line 383, in request
    resp = self.send(prep, **send_kwargs)
  File "/home/nightwish/elfin/local/lib/python2.7/site-packages/requests-2.2.1-py2.7.egg/requests/sessions.py", line 486, in send
    r = adapter.send(request, **kwargs)
  File "/home/nightwish/elfin/local/lib/python2.7/site-packages/requests-2.2.1-py2.7.egg/requests/adapters.py", line 378, in send
    raise ConnectionError(e)
requests.exceptions.ConnectionError: HTTPSConnectionPool(host='api.weixin.qq.com', port=443): Max retries exceeded with url: /cgi-bin/token?secret=37e8ff0ffbe0cfa1589787cb42ab3b54&grant_type=client_credential&appid=wx16b6a22daa10d5c1 (Caused by <class 'socket.error'>: [Errno 110] Connection timed out)
Traceback (most recent call last):
  File "/home/nightwish/elfin/scripts/get_access_token.py", line 40, in <module>
    get_access_token()
  File "/home/nightwish/elfin/scripts/get_access_token.py", line 29, in get_access_token
    r = requests.get(URL, params=params)
  File "/home/nightwish/elfin/local/lib/python2.7/site-packages/requests-2.2.1-py2.7.egg/requests/api.py", line 55, in get
    return request('get', url, **kwargs)
  File "/home/nightwish/elfin/local/lib/python2.7/site-packages/requests-2.2.1-py2.7.egg/requests/api.py", line 44, in request
    return session.request(method=method, url=url, **kwargs)
  File "/home/nightwish/elfin/local/lib/python2.7/site-packages/requests-2.2.1-py2.7.egg/requests/sessions.py", line 383, in request
    resp = self.send(prep, **send_kwargs)
  File "/home/nightwish/elfin/local/lib/python2.7/site-packages/requests-2.2.1-py2.7.egg/requests/sessions.py", line 486, in send
    r = adapter.send(request, **kwargs)
  File "/home/nightwish/elfin/local/lib/python2.7/site-packages/requests-2.2.1-py2.7.egg/requests/adapters.py", line 378, in send
    raise ConnectionError(e)
requests.exceptions.ConnectionError: HTTPSConnectionPool(host='api.weixin.qq.com', port=443): Max retries exceeded with url: /cgi-bin/token?secret=37e8ff0ffbe0cfa1589787cb42ab3b54&grant_type=client_credential&appid=wx16b6a22daa10d5c1 (Caused by <class 'socket.error'>: [Errno 110] Connection timed out)
Traceback (most recent call last):
  File "/home/nightwish/elfin/scripts/get_access_token.py", line 40, in <module>
    get_access_token()
  File "/home/nightwish/elfin/scripts/get_access_token.py", line 29, in get_access_token
    r = requests.get(URL, params=params)
  File "/home/nightwish/elfin/local/lib/python2.7/site-packages/requests-2.2.1-py2.7.egg/requests/api.py", line 55, in get
    return request('get', url, **kwargs)
  File "/home/nightwish/elfin/local/lib/python2.7/site-packages/requests-2.2.1-py2.7.egg/requests/api.py", line 44, in request
    return session.request(method=method, url=url, **kwargs)
  File "/home/nightwish/elfin/local/lib/python2.7/site-packages/requests-2.2.1-py2.7.egg/requests/sessions.py", line 383, in request
    resp = self.send(prep, **send_kwargs)
  File "/home/nightwish/elfin/local/lib/python2.7/site-packages/requests-2.2.1-py2.7.egg/requests/sessions.py", line 486, in send
    r = adapter.send(request, **kwargs)
  File "/home/nightwish/elfin/local/lib/python2.7/site-packages/requests-2.2.1-py2.7.egg/requests/adapters.py", line 378, in send
    raise ConnectionError(e)
requests.exceptions.ConnectionError: HTTPSConnectionPool(host='api.weixin.qq.com', port=443): Max retries exceeded with url: /cgi-bin/token?secret=37e8ff0ffbe0cfa1589787cb42ab3b54&grant_type=client_credential&appid=wx16b6a22daa10d5c1 (Caused by <class 'socket.error'>: [Errno 110] Connection timed out)
Traceback (most recent call last):
  File "/home/nightwish/elfin/scripts/get_access_token.py", line 40, in <module>
    get_access_token()
  File "/home/nightwish/elfin/scripts/get_access_token.py", line 29, in get_access_token
    r = requests.get(URL, params=params)
  File "/home/nightwish/elfin/local/lib/python2.7/site-packages/requests-2.2.1-py2.7.egg/requests/api.py", line 55, in get
    return request('get', url, **kwargs)
  File "/home/nightwish/elfin/local/lib/python2.7/site-packages/requests-2.2.1-py2.7.egg/requests/api.py", line 44, in request
    return session.request(method=method, url=url, **kwargs)
  File "/home/nightwish/elfin/local/lib/python2.7/site-packages/requests-2.2.1-py2.7.egg/requests/sessions.py", line 383, in request
    resp = self.send(prep, **send_kwargs)
  File "/home/nightwish/elfin/local/lib/python2.7/site-packages/requests-2.2.1-py2.7.egg/requests/sessions.py", line 486, in send
    r = adapter.send(request, **kwargs)
  File "/home/nightwish/elfin/local/lib/python2.7/site-packages/requests-2.2.1-py2.7.egg/requests/adapters.py", line 378, in send
    raise ConnectionError(e)
requests.exceptions.ConnectionError: HTTPSConnectionPool(host='api.weixin.qq.com', port=443): Max retries exceeded with url: /cgi-bin/token?secret=37e8ff0ffbe0cfa1589787cb42ab3b54&grant_type=client_credential&appid=wx16b6a22daa10d5c1 (Caused by <class 'socket.error'>: [Errno 110] Connection timed out)
Traceback (most recent call last):
  File "/home/nightwish/elfin/scripts/get_access_token.py", line 40, in <module>
    get_access_token()
  File "/home/nightwish/elfin/scripts/get_access_token.py", line 29, in get_access_token
    r = requests.get(URL, params=params)
  File "/home/nightwish/elfin/local/lib/python2.7/site-packages/requests-2.2.1-py2.7.egg/requests/api.py", line 55, in get
    return request('get', url, **kwargs)
  File "/home/nightwish/elfin/local/lib/python2.7/site-packages/requests-2.2.1-py2.7.egg/requests/api.py", line 44, in request
    return session.request(method=method, url=url, **kwargs)
  File "/home/nightwish/elfin/local/lib/python2.7/site-packages/requests-2.2.1-py2.7.egg/requests/sessions.py", line 383, in request
    resp = self.send(prep, **send_kwargs)
  File "/home/nightwish/elfin/local/lib/python2.7/site-packages/requests-2.2.1-py2.7.egg/requests/sessions.py", line 486, in send
    r = adapter.send(request, **kwargs)
  File "/home/nightwish/elfin/local/lib/python2.7/site-packages/requests-2.2.1-py2.7.egg/requests/adapters.py", line 378, in send
    raise ConnectionError(e)
requests.exceptions.ConnectionError: HTTPSConnectionPool(host='api.weixin.qq.com', port=443): Max retries exceeded with url: /cgi-bin/token?secret=37e8ff0ffbe0cfa1589787cb42ab3b54&grant_type=client_credential&appid=wx16b6a22daa10d5c1 (Caused by <class 'socket.error'>: [Errno 110] Connection timed out)
Traceback (most recent call last):
  File "/home/nightwish/elfin/scripts/get_access_token.py", line 40, in <module>
    get_access_token()
  File "/home/nightwish/elfin/scripts/get_access_token.py", line 29, in get_access_token
    r = requests.get(URL, params=params)
  File "/home/nightwish/elfin/local/lib/python2.7/site-packages/requests-2.2.1-py2.7.egg/requests/api.py", line 55, in get
    return request('get', url, **kwargs)
  File "/home/nightwish/elfin/local/lib/python2.7/site-packages/requests-2.2.1-py2.7.egg/requests/api.py", line 44, in request
    return session.request(method=method, url=url, **kwargs)
  File "/home/nightwish/elfin/local/lib/python2.7/site-packages/requests-2.2.1-py2.7.egg/requests/sessions.py", line 383, in request
    resp = self.send(prep, **send_kwargs)
  File "/home/nightwish/elfin/local/lib/python2.7/site-packages/requests-2.2.1-py2.7.egg/requests/sessions.py", line 486, in send
    r = adapter.send(request, **kwargs)
  File "/home/nightwish/elfin/local/lib/python2.7/site-packages/requests-2.2.1-py2.7.egg/requests/adapters.py", line 378, in send
    raise ConnectionError(e)
requests.exceptions.ConnectionError: HTTPSConnectionPool(host='api.weixin.qq.com', port=443): Max retries exceeded with url: /cgi-bin/token?secret=37e8ff0ffbe0cfa1589787cb42ab3b54&grant_type=client_credential&appid=wx16b6a22daa10d5c1 (Caused by <class 'socket.error'>: [Errno 110] Connection timed out)
Traceback (most recent call last):
  File "/home/nightwish/elfin/scripts/get_access_token.py", line 40, in <module>
    get_access_token()
  File "/home/nightwish/elfin/scripts/get_access_token.py", line 29, in get_access_token
    r = requests.get(URL, params=params)
  File "/home/nightwish/elfin/local/lib/python2.7/site-packages/requests-2.2.1-py2.7.egg/requests/api.py", line 55, in get
    return request('get', url, **kwargs)
  File "/home/nightwish/elfin/local/lib/python2.7/site-packages/requests-2.2.1-py2.7.egg/requests/api.py", line 44, in request
    return session.request(method=method, url=url, **kwargs)
  File "/home/nightwish/elfin/local/lib/python2.7/site-packages/requests-2.2.1-py2.7.egg/requests/sessions.py", line 383, in request
    resp = self.send(prep, **send_kwargs)
  File "/home/nightwish/elfin/local/lib/python2.7/site-packages/requests-2.2.1-py2.7.egg/requests/sessions.py", line 486, in send
    r = adapter.send(request, **kwargs)
  File "/home/nightwish/elfin/local/lib/python2.7/site-packages/requests-2.2.1-py2.7.egg/requests/adapters.py", line 378, in send
    raise ConnectionError(e)
requests.exceptions.ConnectionError: HTTPSConnectionPool(host='api.weixin.qq.com', port=443): Max retries exceeded with url: /cgi-bin/token?secret=37e8ff0ffbe0cfa1589787cb42ab3b54&grant_type=client_credential&appid=wx16b6a22daa10d5c1 (Caused by <class 'socket.error'>: [Errno 110] Connection timed out)
Traceback (most recent call last):
  File "/home/nightwish/elfin/scripts/get_access_token.py", line 40, in <module>
    get_access_token()
  File "/home/nightwish/elfin/scripts/get_access_token.py", line 29, in get_access_token
    r = requests.get(URL, params=params)
  File "/home/nightwish/elfin/local/lib/python2.7/site-packages/requests-2.2.1-py2.7.egg/requests/api.py", line 55, in get
    return request('get', url, **kwargs)
  File "/home/nightwish/elfin/local/lib/python2.7/site-packages/requests-2.2.1-py2.7.egg/requests/api.py", line 44, in request
    return session.request(method=method, url=url, **kwargs)
  File "/home/nightwish/elfin/local/lib/python2.7/site-packages/requests-2.2.1-py2.7.egg/requests/sessions.py", line 383, in request
    resp = self.send(prep, **send_kwargs)
  File "/home/nightwish/elfin/local/lib/python2.7/site-packages/requests-2.2.1-py2.7.egg/requests/sessions.py", line 486, in send
    r = adapter.send(request, **kwargs)
  File "/home/nightwish/elfin/local/lib/python2.7/site-packages/requests-2.2.1-py2.7.egg/requests/adapters.py", line 378, in send
    raise ConnectionError(e)
requests.exceptions.ConnectionError: HTTPSConnectionPool(host='api.weixin.qq.com', port=443): Max retries exceeded with url: /cgi-bin/token?secret=37e8ff0ffbe0cfa1589787cb42ab3b54&grant_type=client_credential&appid=wx16b6a22daa10d5c1 (Caused by <class 'socket.error'>: [Errno 110] Connection timed out)
Traceback (most recent call last):
  File "/home/nightwish/elfin/scripts/get_access_token.py", line 40, in <module>
    get_access_token()
  File "/home/nightwish/elfin/scripts/get_access_token.py", line 29, in get_access_token
    r = requests.get(URL, params=params)
  File "/home/nightwish/elfin/local/lib/python2.7/site-packages/requests-2.2.1-py2.7.egg/requests/api.py", line 55, in get
    return request('get', url, **kwargs)
  File "/home/nightwish/elfin/local/lib/python2.7/site-packages/requests-2.2.1-py2.7.egg/requests/api.py", line 44, in request
    return session.request(method=method, url=url, **kwargs)
  File "/home/nightwish/elfin/local/lib/python2.7/site-packages/requests-2.2.1-py2.7.egg/requests/sessions.py", line 383, in request
    resp = self.send(prep, **send_kwargs)
  File "/home/nightwish/elfin/local/lib/python2.7/site-packages/requests-2.2.1-py2.7.egg/requests/sessions.py", line 486, in send
    r = adapter.send(request, **kwargs)
  File "/home/nightwish/elfin/local/lib/python2.7/site-packages/requests-2.2.1-py2.7.egg/requests/adapters.py", line 378, in send
    raise ConnectionError(e)
requests.exceptions.ConnectionError: HTTPSConnectionPool(host='api.weixin.qq.com', port=443): Max retries exceeded with url: /cgi-bin/token?secret=37e8ff0ffbe0cfa1589787cb42ab3b54&grant_type=client_credential&appid=wx16b6a22daa10d5c1 (Caused by <class 'socket.error'>: [Errno 110] Connection timed out)
Traceback (most recent call last):
  File "/home/nightwish/elfin/scripts/get_access_token.py", line 40, in <module>
    get_access_token()
  File "/home/nightwish/elfin/scripts/get_access_token.py", line 29, in get_access_token
    r = requests.get(URL, params=params)
  File "/home/nightwish/elfin/local/lib/python2.7/site-packages/requests-2.2.1-py2.7.egg/requests/api.py", line 55, in get
    return request('get', url, **kwargs)
  File "/home/nightwish/elfin/local/lib/python2.7/site-packages/requests-2.2.1-py2.7.egg/requests/api.py", line 44, in request
    return session.request(method=method, url=url, **kwargs)
  File "/home/nightwish/elfin/local/lib/python2.7/site-packages/requests-2.2.1-py2.7.egg/requests/sessions.py", line 383, in request
    resp = self.send(prep, **send_kwargs)
  File "/home/nightwish/elfin/local/lib/python2.7/site-packages/requests-2.2.1-py2.7.egg/requests/sessions.py", line 486, in send
    r = adapter.send(request, **kwargs)
  File "/home/nightwish/elfin/local/lib/python2.7/site-packages/requests-2.2.1-py2.7.egg/requests/adapters.py", line 378, in send
    raise ConnectionError(e)
requests.exceptions.ConnectionError: HTTPSConnectionPool(host='api.weixin.qq.com', port=443): Max retries exceeded with url: /cgi-bin/token?secret=37e8ff0ffbe0cfa1589787cb42ab3b54&grant_type=client_credential&appid=wx16b6a22daa10d5c1 (Caused by <class 'socket.error'>: [Errno 110] Connection timed out)
Traceback (most recent call last):
  File "/home/nightwish/elfin/scripts/get_access_token.py", line 40, in <module>
    get_access_token()
  File "/home/nightwish/elfin/scripts/get_access_token.py", line 29, in get_access_token
    r = requests.get(URL, params=params)
  File "/home/nightwish/elfin/local/lib/python2.7/site-packages/requests-2.2.1-py2.7.egg/requests/api.py", line 55, in get
    return request('get', url, **kwargs)
  File "/home/nightwish/elfin/local/lib/python2.7/site-packages/requests-2.2.1-py2.7.egg/requests/api.py", line 44, in request
    return session.request(method=method, url=url, **kwargs)
  File "/home/nightwish/elfin/local/lib/python2.7/site-packages/requests-2.2.1-py2.7.egg/requests/sessions.py", line 383, in request
    resp = self.send(prep, **send_kwargs)
  File "/home/nightwish/elfin/local/lib/python2.7/site-packages/requests-2.2.1-py2.7.egg/requests/sessions.py", line 486, in send
    r = adapter.send(request, **kwargs)
  File "/home/nightwish/elfin/local/lib/python2.7/site-packages/requests-2.2.1-py2.7.egg/requests/adapters.py", line 378, in send
    raise ConnectionError(e)
requests.exceptions.ConnectionError: HTTPSConnectionPool(host='api.weixin.qq.com', port=443): Max retries exceeded with url: /cgi-bin/token?secret=37e8ff0ffbe0cfa1589787cb42ab3b54&grant_type=client_credential&appid=wx16b6a22daa10d5c1 (Caused by <class 'socket.error'>: [Errno 110] Connection timed out)
Traceback (most recent call last):
  File "/home/nightwish/elfin/scripts/get_access_token.py", line 40, in <module>
    get_access_token()
  File "/home/nightwish/elfin/scripts/get_access_token.py", line 29, in get_access_token
    r = requests.get(URL, params=params)
  File "/home/nightwish/elfin/local/lib/python2.7/site-packages/requests-2.2.1-py2.7.egg/requests/api.py", line 55, in get
    return request('get', url, **kwargs)
  File "/home/nightwish/elfin/local/lib/python2.7/site-packages/requests-2.2.1-py2.7.egg/requests/api.py", line 44, in request
    return session.request(method=method, url=url, **kwargs)
  File "/home/nightwish/elfin/local/lib/python2.7/site-packages/requests-2.2.1-py2.7.egg/requests/sessions.py", line 383, in request
    resp = self.send(prep, **send_kwargs)
  File "/home/nightwish/elfin/local/lib/python2.7/site-packages/requests-2.2.1-py2.7.egg/requests/sessions.py", line 486, in send
    r = adapter.send(request, **kwargs)
  File "/home/nightwish/elfin/local/lib/python2.7/site-packages/requests-2.2.1-py2.7.egg/requests/adapters.py", line 378, in send
    raise ConnectionError(e)
requests.exceptions.ConnectionError: HTTPSConnectionPool(host='api.weixin.qq.com', port=443): Max retries exceeded with url: /cgi-bin/token?secret=37e8ff0ffbe0cfa1589787cb42ab3b54&grant_type=client_credential&appid=wx16b6a22daa10d5c1 (Caused by <class 'socket.error'>: [Errno 110] Connection timed out)
Traceback (most recent call last):
  File "/home/nightwish/elfin/scripts/get_access_token.py", line 40, in <module>
    get_access_token()
  File "/home/nightwish/elfin/scripts/get_access_token.py", line 29, in get_access_token
    r = requests.get(URL, params=params)
  File "/home/nightwish/elfin/local/lib/python2.7/site-packages/requests-2.2.1-py2.7.egg/requests/api.py", line 55, in get
    return request('get', url, **kwargs)
  File "/home/nightwish/elfin/local/lib/python2.7/site-packages/requests-2.2.1-py2.7.egg/requests/api.py", line 44, in request
    return session.request(method=method, url=url, **kwargs)
  File "/home/nightwish/elfin/local/lib/python2.7/site-packages/requests-2.2.1-py2.7.egg/requests/sessions.py", line 383, in request
    resp = self.send(prep, **send_kwargs)
  File "/home/nightwish/elfin/local/lib/python2.7/site-packages/requests-2.2.1-py2.7.egg/requests/sessions.py", line 486, in send
    r = adapter.send(request, **kwargs)
  File "/home/nightwish/elfin/local/lib/python2.7/site-packages/requests-2.2.1-py2.7.egg/requests/adapters.py", line 378, in send
    raise ConnectionError(e)
requests.exceptions.ConnectionError: HTTPSConnectionPool(host='api.weixin.qq.com', port=443): Max retries exceeded with url: /cgi-bin/token?secret=37e8ff0ffbe0cfa1589787cb42ab3b54&grant_type=client_credential&appid=wx16b6a22daa10d5c1 (Caused by <class 'socket.error'>: [Errno 110] Connection timed out)
Traceback (most recent call last):
  File "/home/nightwish/elfin/scripts/get_access_token.py", line 40, in <module>
    get_access_token()
  File "/home/nightwish/elfin/scripts/get_access_token.py", line 29, in get_access_token
    r = requests.get(URL, params=params)
  File "/home/nightwish/elfin/local/lib/python2.7/site-packages/requests-2.2.1-py2.7.egg/requests/api.py", line 55, in get
    return request('get', url, **kwargs)
  File "/home/nightwish/elfin/local/lib/python2.7/site-packages/requests-2.2.1-py2.7.egg/requests/api.py", line 44, in request
    return session.request(method=method, url=url, **kwargs)
  File "/home/nightwish/elfin/local/lib/python2.7/site-packages/requests-2.2.1-py2.7.egg/requests/sessions.py", line 383, in request
    resp = self.send(prep, **send_kwargs)
  File "/home/nightwish/elfin/local/lib/python2.7/site-packages/requests-2.2.1-py2.7.egg/requests/sessions.py", line 486, in send
    r = adapter.send(request, **kwargs)
  File "/home/nightwish/elfin/local/lib/python2.7/site-packages/requests-2.2.1-py2.7.egg/requests/adapters.py", line 378, in send
    raise ConnectionError(e)
requests.exceptions.ConnectionError: HTTPSConnectionPool(host='api.weixin.qq.com', port=443): Max retries exceeded with url: /cgi-bin/token?secret=37e8ff0ffbe0cfa1589787cb42ab3b54&grant_type=client_credential&appid=wx16b6a22daa10d5c1 (Caused by <class 'socket.error'>: [Errno 110] Connection timed out)
Traceback (most recent call last):
  File "/home/nightwish/elfin/scripts/get_access_token.py", line 40, in <module>
    get_access_token()
  File "/home/nightwish/elfin/scripts/get_access_token.py", line 29, in get_access_token
    r = requests.get(URL, params=params)
  File "/home/nightwish/elfin/local/lib/python2.7/site-packages/requests-2.2.1-py2.7.egg/requests/api.py", line 55, in get
    return request('get', url, **kwargs)
  File "/home/nightwish/elfin/local/lib/python2.7/site-packages/requests-2.2.1-py2.7.egg/requests/api.py", line 44, in request
    return session.request(method=method, url=url, **kwargs)
  File "/home/nightwish/elfin/local/lib/python2.7/site-packages/requests-2.2.1-py2.7.egg/requests/sessions.py", line 383, in request
    resp = self.send(prep, **send_kwargs)
  File "/home/nightwish/elfin/local/lib/python2.7/site-packages/requests-2.2.1-py2.7.egg/requests/sessions.py", line 486, in send
    r = adapter.send(request, **kwargs)
  File "/home/nightwish/elfin/local/lib/python2.7/site-packages/requests-2.2.1-py2.7.egg/requests/adapters.py", line 378, in send
    raise ConnectionError(e)
requests.exceptions.ConnectionError: HTTPSConnectionPool(host='api.weixin.qq.com', port=443): Max retries exceeded with url: /cgi-bin/token?secret=37e8ff0ffbe0cfa1589787cb42ab3b54&grant_type=client_credential&appid=wx16b6a22daa10d5c1 (Caused by <class 'socket.error'>: [Errno 110] Connection timed out)
Traceback (most recent call last):
  File "/home/nightwish/elfin/scripts/get_access_token.py", line 40, in <module>
    get_access_token()
  File "/home/nightwish/elfin/scripts/get_access_token.py", line 29, in get_access_token
    r = requests.get(URL, params=params)
  File "/home/nightwish/elfin/local/lib/python2.7/site-packages/requests-2.2.1-py2.7.egg/requests/api.py", line 55, in get
    return request('get', url, **kwargs)
  File "/home/nightwish/elfin/local/lib/python2.7/site-packages/requests-2.2.1-py2.7.egg/requests/api.py", line 44, in request
    return session.request(method=method, url=url, **kwargs)
  File "/home/nightwish/elfin/local/lib/python2.7/site-packages/requests-2.2.1-py2.7.egg/requests/sessions.py", line 383, in request
    resp = self.send(prep, **send_kwargs)
  File "/home/nightwish/elfin/local/lib/python2.7/site-packages/requests-2.2.1-py2.7.egg/requests/sessions.py", line 486, in send
    r = adapter.send(request, **kwargs)
  File "/home/nightwish/elfin/local/lib/python2.7/site-packages/requests-2.2.1-py2.7.egg/requests/adapters.py", line 378, in send
    raise ConnectionError(e)
requests.exceptions.ConnectionError: HTTPSConnectionPool(host='api.weixin.qq.com', port=443): Max retries exceeded with url: /cgi-bin/token?secret=37e8ff0ffbe0cfa1589787cb42ab3b54&grant_type=client_credential&appid=wx16b6a22daa10d5c1 (Caused by <class 'socket.error'>: [Errno 110] Connection timed out)
Traceback (most recent call last):
  File "/home/nightwish/elfin/scripts/get_access_token.py", line 40, in <module>
    get_access_token()
  File "/home/nightwish/elfin/scripts/get_access_token.py", line 29, in get_access_token
    r = requests.get(URL, params=params)
  File "/home/nightwish/elfin/local/lib/python2.7/site-packages/requests-2.2.1-py2.7.egg/requests/api.py", line 55, in get
    return request('get', url, **kwargs)
  File "/home/nightwish/elfin/local/lib/python2.7/site-packages/requests-2.2.1-py2.7.egg/requests/api.py", line 44, in request
    return session.request(method=method, url=url, **kwargs)
  File "/home/nightwish/elfin/local/lib/python2.7/site-packages/requests-2.2.1-py2.7.egg/requests/sessions.py", line 383, in request
    resp = self.send(prep, **send_kwargs)
  File "/home/nightwish/elfin/local/lib/python2.7/site-packages/requests-2.2.1-py2.7.egg/requests/sessions.py", line 486, in send
    r = adapter.send(request, **kwargs)
  File "/home/nightwish/elfin/local/lib/python2.7/site-packages/requests-2.2.1-py2.7.egg/requests/adapters.py", line 378, in send
    raise ConnectionError(e)
requests.exceptions.ConnectionError: HTTPSConnectionPool(host='api.weixin.qq.com', port=443): Max retries exceeded with url: /cgi-bin/token?secret=37e8ff0ffbe0cfa1589787cb42ab3b54&grant_type=client_credential&appid=wx16b6a22daa10d5c1 (Caused by <class 'socket.error'>: [Errno 110] Connection timed out)
Traceback (most recent call last):
  File "/home/nightwish/elfin/scripts/get_access_token.py", line 40, in <module>
    get_access_token()
  File "/home/nightwish/elfin/scripts/get_access_token.py", line 29, in get_access_token
    r = requests.get(URL, params=params)
  File "/home/nightwish/elfin/local/lib/python2.7/site-packages/requests-2.2.1-py2.7.egg/requests/api.py", line 55, in get
    return request('get', url, **kwargs)
  File "/home/nightwish/elfin/local/lib/python2.7/site-packages/requests-2.2.1-py2.7.egg/requests/api.py", line 44, in request
    return session.request(method=method, url=url, **kwargs)
  File "/home/nightwish/elfin/local/lib/python2.7/site-packages/requests-2.2.1-py2.7.egg/requests/sessions.py", line 383, in request
    resp = self.send(prep, **send_kwargs)
  File "/home/nightwish/elfin/local/lib/python2.7/site-packages/requests-2.2.1-py2.7.egg/requests/sessions.py", line 486, in send
    r = adapter.send(request, **kwargs)
  File "/home/nightwish/elfin/local/lib/python2.7/site-packages/requests-2.2.1-py2.7.egg/requests/adapters.py", line 378, in send
    raise ConnectionError(e)
requests.exceptions.ConnectionError: HTTPSConnectionPool(host='api.weixin.qq.com', port=443): Max retries exceeded with url: /cgi-bin/token?secret=37e8ff0ffbe0cfa1589787cb42ab3b54&grant_type=client_credential&appid=wx16b6a22daa10d5c1 (Caused by <class 'socket.error'>: [Errno 110] Connection timed out)
Traceback (most recent call last):
  File "/home/nightwish/elfin/scripts/get_access_token.py", line 40, in <module>
    get_access_token()
  File "/home/nightwish/elfin/scripts/get_access_token.py", line 29, in get_access_token
    r = requests.get(URL, params=params)
  File "/home/nightwish/elfin/local/lib/python2.7/site-packages/requests-2.2.1-py2.7.egg/requests/api.py", line 55, in get
    return request('get', url, **kwargs)
  File "/home/nightwish/elfin/local/lib/python2.7/site-packages/requests-2.2.1-py2.7.egg/requests/api.py", line 44, in request
    return session.request(method=method, url=url, **kwargs)
  File "/home/nightwish/elfin/local/lib/python2.7/site-packages/requests-2.2.1-py2.7.egg/requests/sessions.py", line 383, in request
    resp = self.send(prep, **send_kwargs)
  File "/home/nightwish/elfin/local/lib/python2.7/site-packages/requests-2.2.1-py2.7.egg/requests/sessions.py", line 486, in send
    r = adapter.send(request, **kwargs)
  File "/home/nightwish/elfin/local/lib/python2.7/site-packages/requests-2.2.1-py2.7.egg/requests/adapters.py", line 378, in send
    raise ConnectionError(e)
requests.exceptions.ConnectionError: HTTPSConnectionPool(host='api.weixin.qq.com', port=443): Max retries exceeded with url: /cgi-bin/token?secret=37e8ff0ffbe0cfa1589787cb42ab3b54&grant_type=client_credential&appid=wx16b6a22daa10d5c1 (Caused by <class 'socket.error'>: [Errno 110] Connection timed out)
Traceback (most recent call last):
  File "/home/nightwish/elfin/scripts/get_access_token.py", line 40, in <module>
    get_access_token()
  File "/home/nightwish/elfin/scripts/get_access_token.py", line 29, in get_access_token
    r = requests.get(URL, params=params)
  File "/home/nightwish/elfin/local/lib/python2.7/site-packages/requests-2.2.1-py2.7.egg/requests/api.py", line 55, in get
    return request('get', url, **kwargs)
  File "/home/nightwish/elfin/local/lib/python2.7/site-packages/requests-2.2.1-py2.7.egg/requests/api.py", line 44, in request
    return session.request(method=method, url=url, **kwargs)
  File "/home/nightwish/elfin/local/lib/python2.7/site-packages/requests-2.2.1-py2.7.egg/requests/sessions.py", line 383, in request
    resp = self.send(prep, **send_kwargs)
  File "/home/nightwish/elfin/local/lib/python2.7/site-packages/requests-2.2.1-py2.7.egg/requests/sessions.py", line 486, in send
    r = adapter.send(request, **kwargs)
  File "/home/nightwish/elfin/local/lib/python2.7/site-packages/requests-2.2.1-py2.7.egg/requests/adapters.py", line 378, in send
    raise ConnectionError(e)
requests.exceptions.ConnectionError: HTTPSConnectionPool(host='api.weixin.qq.com', port=443): Max retries exceeded with url: /cgi-bin/token?secret=37e8ff0ffbe0cfa1589787cb42ab3b54&grant_type=client_credential&appid=wx16b6a22daa10d5c1 (Caused by <class 'socket.error'>: [Errno 110] Connection timed out)
Traceback (most recent call last):
  File "/home/nightwish/elfin/local/lib/python2.7/site-packages/gevent/greenlet.py", line 327, in run
    result = self._run(*self.args, **self.kwargs)
  File "/home/nightwish/elfin/scripts/simi.py", line 17, in simi
    return respons['response']
KeyError: 'response'
<Greenlet at 0x8e1f3ec: simi(u'\u8131\u5457')> failed with KeyError

Traceback (most recent call last):
  File "/home/nightwish/elfin/local/lib/python2.7/site-packages/gevent/greenlet.py", line 327, in run
    result = self._run(*self.args, **self.kwargs)
  File "/home/nightwish/elfin/scripts/simi.py", line 17, in simi
    return respons['response']
KeyError: 'response'
<Greenlet at 0x8fdf25c: simi(u'\u3002')> failed with KeyError

all output going to: /home/nightwish/elfin/log/mongo.log
Traceback (most recent call last):
  File "/home/nightwish/elfin/local/lib/python2.7/site-packages/gevent/greenlet.py", line 327, in run
    result = self._run(*self.args, **self.kwargs)
  File "/home/nightwish/elfin/scripts/simi.py", line 17, in simi
    return respons['response']
KeyError: 'response'
<Greenlet at 0x9fe0d4c: simi(u'\u3002\u3002\u3002\u3002\u3002')> failed with KeyError

Traceback (most recent call last):
  File "/home/nightwish/elfin/local/lib/python2.7/site-packages/gevent/greenlet.py", line 327, in run
    result = self._run(*self.args, **self.kwargs)
  File "/home/nightwish/elfin/scripts/simi.py", line 17, in simi
    return respons['response']
KeyError: 'response'
<Greenlet at 0xa0e793c: simi(u'\u3002\u3002\u3002\u3002\u3002\u3002\u3002\u3002)> failed with KeyError

Traceback (most recent call last):
  File "/home/nightwish/elfin/local/lib/python2.7/site-packages/gevent/greenlet.py", line 327, in run
    result = self._run(*self.args, **self.kwargs)
  File "/home/nightwish/elfin/scripts/simi.py", line 17, in simi
    return respons['response']
KeyError: 'response'
<Greenlet at 0xa0e793c: simi(u'\u3002\u3002\u3002\u3002\u3002\u3002\u3002\u3002)> failed with KeyError

Traceback (most recent call last):
  File "/home/nightwish/elfin/local/lib/python2.7/site-packages/gevent/greenlet.py", line 327, in run
    result = self._run(*self.args, **self.kwargs)
  File "/home/nightwish/elfin/scripts/simi.py", line 17, in simi
    return respons['response']
KeyError: 'response'
<Greenlet at 0xa0e793c: simi(u'\uff0c\uff0c\uff0c\uff0c\uff0c\uff0c\uff0c\uff0c)> failed with KeyError

Traceback (most recent call last):
  File "/home/nightwish/elfin/local/lib/python2.7/site-packages/gevent/greenlet.py", line 327, in run
    result = self._run(*self.args, **self.kwargs)
  File "/home/nightwish/elfin/scripts/simi.py", line 17, in simi
    return respons['response']
KeyError: 'response'
<Greenlet at 0xa0e7f2c: simi(u'\uf8ff ')> failed with KeyError

all output going to: /home/nightwish/elfin/log/mongo.log
Traceback (most recent call last):
  File "/home/nightwish/elfin/local/lib/python2.7/site-packages/gevent/greenlet.py", line 327, in run
    result = self._run(*self.args, **self.kwargs)
  File "/home/nightwish/elfin/scripts/simi.py", line 17, in simi
    return respons['response']
KeyError: 'response'
<Greenlet at 0xa1dbb1c: simi('0928743')> failed with KeyError

Traceback (most recent call last):
  File "/home/nightwish/elfin/local/lib/python2.7/site-packages/gevent/greenlet.py", line 327, in run
    result = self._run(*self.args, **self.kwargs)
  File "/home/nightwish/elfin/scripts/simi.py", line 17, in simi
    return respons['response']
KeyError: 'response'
<Greenlet at 0xa1dbb1c: simi('S42H')> failed with KeyError

all output going to: /home/nightwish/elfin/log/mongo.log
Traceback (most recent call last):
  File "/usr/local/lib/python2.7/dist-packages/gevent/greenlet.py", line 327, in run
    result = self._run(*self.args, **self.kwargs)
  File "/home/nightwish/elfin/scripts/simi.py", line 17, in simi
    return respons['response']
KeyError: 'response'
<Greenlet at 0x9b3e0cc: simi(u'\ue408')> failed with KeyError

